Workbook

Sheet Data
A1: CODE | B1: NAME | D1: IATA | E1: Aeropuerto origen | G1: IATA | H1: Aeropuerto origen | J1: TYPE OF FLIGHT | K1: Designador
A2: 1A | B2: FBONLU | D2: ACA-NLU | E2: Acapulco | G2: NLU-ACA | H2: Acapulco | J2: A | K2: 2
A3: 2D | B3: EASTERN AIRLINES | D3: AFW-NLU | E3: Fort Worth | G3: NLU-AFW | H3: Fort Worth | J3: H | K3: 2
A4: 5D | B4: Aeromexico Connect | D4: AGU-NLU | E4: Aguascalientes | G4: NLU-AGU | H4: Aguascalientes | J4: F | K4: 2
A5: 5R | B5: Rutaca Airlines | D5: AMS-NLU | E5: Amsterdam | G5: NLU-AMS | H5: Amsterdam | J5: J | K5: 1
A6: 5X | B6: United Parcel Service | D6: ANC-NLU | E6: Anchorage | G6: NLU-ANC | H6: Anchorage | J6: C | K6: 1
A7: 5Y | B7: Atlas Air | D7: ATH-NLU | E7: Atenas | G7: NLU-ATH | H7: Atenas | J7: P | K7: 2
A8: 6R | B8: AeroUnión | D8: ATL-NLU | E8: Atlanta | G8: NLU-ATL | H8: Atlanta | J8: O | K8: 3
A9: AA | B9: American Airlines | D9: AUS-NLU | E9: Austin | G9: NLU-AUS | H9: Austin | J9: I | K9: 3
A10: AC | B10: Air Canada | D10: AZA-NLU | E10: Phoenix | G10: NLU-AZA | H10: Phoenix | J10: G | K10: 1
A11: AF | B11: Air France | D11: BCN-NLU | E11: Barcelona | G11: NLU-BCN | H11: Barcelona | J11: X | K11: 1
A12: AM | B12: Aeromexico | D12: BFI-NLU | E12: Seattle | G12: NLU-BFI | H12: Seattle
A13: AR | B13: Aerolíneas Argentinas | D13: BJX-NLU | E13: Bajío | G13: NLU-BJX | H13: Bajío
A14: AV | B14: Avianca | D14: BOG-NLU | E14: Bogotá | G14: NLU-BOG | H14: Bogotá
A15: AY | B15: Finnair | D15: BRO-NLU | E15: Condado de Cameron | G15: NLU-BRO | H15: Condado de Cameron
A16: BA | B16: British Airways | D16: BUD-NLU | E16: Budapest | G16: NLU-BUD | H16: Budapest
A17: CA | B17: Air China | D17: BWI-NLU | E17: Washington-Baltimore Int Apt | G17: NLU-BWI | H17: Washington-Baltimore Int Apt
A18: CI | B18: China Airlines | D18: CAN-NLU | E18: Canton Baiyun | G18: NLU-CAN | H18: Canton Baiyun
A19: CM | B19: Copa Airlines | D19: CCS-NLU | E19: Caracas | G19: NLU-CCS | H19: Caracas
A20: CV | B20: Cargolux | D20: CDG-NLU | E20: París | G20: NLU-CDG | H20: París
A21: CX | B21: Cathay Pacific | D21: CEN-NLU | E21: Ciudad Obregón | G21: NLU-CEN | H21: Ciudad Obregón
A22: CZ | B22: China Southerrn | D22: CJS-NLU | E22: Ciudad Juárez | G22: NLU-CJS | H22: Ciudad Juárez
A23: DL | B23: Delta Air Lines | D23: CLQ-NLU | E23: Colima | G23: NLU-CLQ | H23: Colima
... A112: GI | B112: Gridiron Air | D112: NLD-NLU | E112: Nuevo Laredo | G112: NLU-NLD | H112: Nuevo Laredo
D113: NLU-NLU | E113: Santa Lucía | G113: NLU-NLU | H113: Santa Lucía
D114: NRT-NLU | E114: Tokyo | G114: NLU-NRT | H114: Tokyo
D115: OAK-NLU | E115: Oakland | G115: NLU-OAK | H115: Oakland
D116: OAX-NLU | E116: Oaxaca | G116: NLU-OAX | H116: Oaxaca
D117: ONT-NLU | E117: Ontario | G117: NLU-ONT | H117: Ontario
D118: ORD-NLU | E118: Chicago | G118: NLU-ORD | H118: Chicago
D119: OSL-NLU | E119: Oslo | G119: NLU-OSL | H119: Oslo
D120: OST-NLU | E120: Oostende Brugge | G120: NLU-OST | H120: Oostende Brugge
D121: PBC-NLU | E121: Puebla | G121: NLU-PBC | H121: Puebla
D122: PBM-NLU | E122: Paramaribo | G122: NLU-PBM | H122: Paramaribo
D123: PDS-NLU | E123: Piedras Negras | G123: NLU-PDS | H123: Piedras Negras
D124: PDX-NLU | E124: Portland | G124: NLU-PDX | H124: Portland
... D237: AEX-NLU | E237: Alexandria, Louisiana | G237: NLU-AEX | H237: Alexandria, Louisiana

Sheet Hoja1
A1: Status | B1: [Arr] Airline code | C1: Aircraft type | D1: [Arr] Flight Designator | E1: [Arr] SIBT | F1: [Arr] Routing | G1: [Arr] Baggage Belts | H1: [Arr] Stand | I1: [Dep] Flight Designator | J1: [Dep] Routing | K1: [Dep] SOBT | L1: [Dep] Service Type | P1: llegadas | Q1: salidas
A2: Last bag | B2: XN | C2: E95 | D2: XN 1765 | E2: 46160.833 | F2: MID-NLU | G2: 1 | H2: 108A | I2: XN 1430 | J2: NLU-GDL | K2: 46162.271 | L2: J | M2: =VLOOKUP(L2,Data!$J$1:$K$13,2,0) -> 1 | N2: =TEXT(E2,"dd/mm/aaaa") -> 18/05/2026 | O2: =TEXT(K2,"dd/mm/aaaa") -> 20/05/2026 | P2: =COUNTIFS($R$2,"="&N2) -> 0 | Q2: =COUNTIFS($R$2,"="&O2) -> 1 | R2: {='Itinerario pasajeros'!A1:J1} -> 46162 | S2: 0 | T2: 0 | U2: 0 | V2: 0 | W2: 0 | X2: 0 | Y2: 0 | Z2: 0 | AA2: 0
A3: Flight activated | B3: VB | C3: 32Q | D3: VB 3677 | E3: 46161.524 | F3: ZIH-NLU | G3: 1 | H3: 132A | I3: VB 7382 | J3: NLU-MTY | K3: 46162.253 | L3: J | M3: =VLOOKUP(L3,Data!$J$1:$K$13,2,0) -> 1 | N3: =TEXT(E3,"dd/mm/aaaa") -> 19/05/2026 | O3: =TEXT(K3,"dd/mm/aaaa") -> 20/05/2026 | P3: =COUNTIFS($R$2,"="&N3) -> 0 | Q3: =COUNTIFS($R$2,"="&O3) -> 1
A4: Flight activated | B4: VB | C4: 32A | D4: VB 7370 | E4: 46161.622 | F4: LAP-NLU | G4: 1 | H4: 107A | I4: VB 9222 | J4: NLU-PXM | K4: 46162.274 | L4: J | M4: =VLOOKUP(L4,Data!$J$1:$K$13,2,0) -> 1 | N4: =TEXT(E4,"dd/mm/aaaa") -> 19/05/2026 | O4: =TEXT(K4,"dd/mm/aaaa") -> 20/05/2026 | P4: =COUNTIFS($R$2,"="&N4) -> 0 | Q4: =COUNTIFS($R$2,"="&O4) -> 1
A5: Flight activated | B5: ZV | C5: CNF | D5: ZV 361 | E5: 46161.712 | F5: CVM-NLU | G5: 1 | H5: 501 | I5: ZV 364 | J5: NLU-CVM | K5: 46162.25 | L5: J | M5: =VLOOKUP(L5,Data!$J$1:$K$13,2,0) -> 1 | N5: =TEXT(E5,"dd/mm/aaaa") -> 19/05/2026 | O5: =TEXT(K5,"dd/mm/aaaa") -> 20/05/2026 | P5: =COUNTIFS($R$2,"="&N5) -> 0 | Q5: =COUNTIFS($R$2,"="&O5) -> 1
A6: Departed from previous airport | B6: VB | C6: 32A | D6: VB 7435 | E6: 46161.844 | F6: VER-NLU | G6: 2 | H6: 505 | I6: VB 9480 | J6: NLU-CEN | K6: 46162.288 | L6: J | M6: =VLOOKUP(L6,Data!$J$1:$K$13,2,0) -> 1 | N6: =TEXT(E6,"dd/mm/aaaa") -> 19/05/2026 | O6: =TEXT(K6,"dd/mm/aaaa") -> 20/05/2026 | P6: =COUNTIFS($R$2,"="&N6) -> 0 | Q6: =COUNTIFS($R$2,"="&O6) -> 1
A7: Flight activated | B7: Y4 | C7: 320 | D7: Y4 7171 | E7: 46161.849 | F7: LAP-NLU | G7: 1 | H7: 109B | I7: Y4 1291 | J7: NLU-GDL | K7: 46162.271 | L7: J | M7: =VLOOKUP(L7,Data!$J$1:$K$13,2,0) -> 1 | N7: =TEXT(E7,"dd/mm/aaaa") -> 19/05/2026 | O7: =TEXT(K7,"dd/mm/aaaa") -> 20/05/2026 | P7: =COUNTIFS($R$2,"="&N7) -> 0 | Q7: =COUNTIFS($R$2,"="&O7) -> 1
A8: Flight activated | B8: Y4 | C8: 32N | D8: Y4 1292 | E8: 46161.852 | F8: GDL-NLU | G8: 1 | H8: 109A | I8: Y4 3960 | J8: NLU-BOG | K8: 46162.025 | L8: J | M8: =VLOOKUP(L8,Data!$J$1:$K$13,2,0) -> 1 | N8: =TEXT(E8,"dd/mm/aaaa") -> 19/05/2026 | O8: =TEXT(K8,"dd/mm/aaaa") -> 20/05/2026 | P8: =COUNTIFS($R$2,"="&N8) -> 0 | Q8: =COUNTIFS($R$2,"="&O8) -> 1
A9: Flight activated | B9: AM | C9: E90 | D9: AM 871 | E9: 46161.863 | F9: VER-NLU | G9: --- | H9: 111A | I9: AM 880 | J9: NLU-PVR | K9: 46162.604 | L9: J | M9: =VLOOKUP(L9,Data!$J$1:$K$13,2,0) -> 1 | N9: =TEXT(E9,"dd/mm/aaaa") -> 19/05/2026 | O9: =TEXT(K9,"dd/mm/aaaa") -> 20/05/2026 | P9: =COUNTIFS($R$2,"="&N9) -> 0 | Q9: =COUNTIFS($R$2,"="&O9) -> 1
A10: Flight activated | B10: VB | C10: 32N | D10: VB 9233 | E10: 46161.944 | F10: MZT-NLU | G10: 1 | H10: 503 | I10: VB 5069 | J10: NLU-TIJ | K10: 46162.25 | L10: J | M10: =VLOOKUP(L10,Data!$J$1:$K$13,2,0) -> 1 | N10: =TEXT(E10,"dd/mm/aaaa") -> 19/05/2026 | O10: =TEXT(K10,"dd/mm/aaaa") -> 20/05/2026 | P10: =COUNTIFS($R$2,"="&N10) -> 0 | Q10: =COUNTIFS($R$2,"="&O10) -> 1
A11: Flight scheduled | B11: XN | C11: 295 | D11: XN 1107 | E11: 46161.955 | F11: MTY-NLU | G11: 3 | H11: 112B | I11: XN 1100 | J11: NLU-MTY | K11: 46162.25 | L11: J | M11: =VLOOKUP(L11,Data!$J$1:$K$13,2,0) -> 1 | N11: =TEXT(E11,"dd/mm/aaaa") -> 19/05/2026 | O11: =TEXT(K11,"dd/mm/aaaa") -> 20/05/2026 | P11: =COUNTIFS($R$2,"="&N11) -> 0 | Q11: =COUNTIFS($R$2,"="&O11) -> 1
A12: Flight scheduled | B12: XN | C12: 295 | D12: XN 1437 | E12: 46161.958 | F12: GDL-NLU | G12: 3 | H12: 108A | I12: XN 1760 | J12: NLU-MID | K12: 46162.285 | L12: J | M12: =VLOOKUP(L12,Data!$J$1:$K$13,2,0) -> 1 | N12: =TEXT(E12,"dd/mm/aaaa") -> 19/05/2026 | O12: =TEXT(K12,"dd/mm/aaaa") -> 20/05/2026 | P12: =COUNTIFS($R$2,"="&N12) -> 0 | Q12: =COUNTIFS($R$2,"="&O12) -> 1
A13: Flight activated | B13: VB | C13: 321 | D13: VB 2288 | E13: 46161.962 | F13: CUN-NLU | G13: 2 | H13: 502 | I13: VB 2281 | J13: NLU-CUN | K13: 46162.264 | L13: J | M13: =VLOOKUP(L13,Data!$J$1:$K$13,2,0) -> 1 | N13: =TEXT(E13,"dd/mm/aaaa") -> 19/05/2026 | O13: =TEXT(K13,"dd/mm/aaaa") -> 20/05/2026 | P13: =COUNTIFS($R$2,"="&N13) -> 0 | Q13: =COUNTIFS($R$2,"="&O13) -> 1
A14: Flight scheduled | B14: E7 | C14: 764/734 | D14: E7 610 | E14: 46161.976 | F14: MID-NLU | G14: --- | H14: 601A | I14: E7 610 | J14: NLU-SLP | K14: 46162.042 | L14: F | M14: =VLOOKUP(L14,Data!$J$1:$K$13,2,0) -> 2 | N14: =TEXT(E14,"dd/mm/aaaa") -> 19/05/2026 | O14: =TEXT(K14,"dd/mm/aaaa") -> 20/05/2026 | P14: =COUNTIFS($R$2,"="&N14) -> 0 | Q14: =COUNTIFS($R$2,"="&O14) -> 1
A15: Flight scheduled | B15: N8 | C15: 74Y | D15: N8 861 | E15: 46161.983 | F15: LAX-NLU | G15: --- | H15: 608 | I15: N8 863 | J15: NLU-JFK | K15: 46162.108 | L15: F | M15: =VLOOKUP(L15,Data!$J$1:$K$13,2,0) -> 2 | N15: =TEXT(E15,"dd/mm/aaaa") -> 19/05/2026 | O15: =TEXT(K15,"dd/mm/aaaa") -> 20/05/2026 | P15: =COUNTIFS($R$2,"="&N15) -> 0 | Q15: =COUNTIFS($R$2,"="&O15) -> 1
A16: Flight scheduled | B16: CV | C16: 74Y | D16: CV 5933 | E16: 46162.007 | F16: GDL-NLU | G16: --- | H16: 607 | I16: CV 5933 | J16: NLU-LUX | K16: 46162.09 | L16: F | M16: =VLOOKUP(L16,Data!$J$1:$K$13,2,0) -> 2 | N16: =TEXT(E16,"dd/mm/aaaa") -> 20/05/2026 | O16: =TEXT(K16,"dd/mm/aaaa") -> 20/05/2026 | P16: =COUNTIFS($R$2,"="&N16) -> 1 | Q16: =COUNTIFS($R$2,"="&O16) -> 1
A17: Flight activated | B17: VB | C17: 321 | D17: VB 5070 | E17: 46162.024 | F17: TIJ-NLU | G17: 2 | H17: 106A | I17: VB 9520 | J17: NLU-GDL | K17: 46162.25 | L17: J | M17: =VLOOKUP(L17,Data!$J$1:$K$13,2,0) -> 1 | N17: =TEXT(E17,"dd/mm/aaaa") -> 20/05/2026 | O17: =TEXT(K17,"dd/mm/aaaa") -> 20/05/2026 | P17: =COUNTIFS($R$2,"="&N17) -> 1 | Q17: =COUNTIFS($R$2,"="&O17) -> 1
A18: Flight scheduled | B18: 6R | C18: 333 | D18: 6R 7081 | E18: 46162.092 | F18: GDL-NLU | G18: --- | H18: 606 | I18: 6R 7081 | J18: NLU-BOG | K18: 46162.155 | L18: F | M18: =VLOOKUP(L18,Data!$J$1:$K$13,2,0) -> 2 | N18: =TEXT(E18,"dd/mm/aaaa") -> 20/05/2026 | O18: =TEXT(K18,"dd/mm/aaaa") -> 20/05/2026 | P18: =COUNTIFS($R$2,"="&N18) -> 1 | Q18: =COUNTIFS($R$2,"="&O18) -> 1
A19: Flight activated | B19: AF | C19: 77F | D19: AF 6720 | E19: 46162.128 | F19: CDG-NLU | G19: --- | H19: 609 | I19: AF 6721 | J19: NLU-GDL | K19: 46162.295 | L19: F | M19: =VLOOKUP(L19,Data!$J$1:$K$13,2,0) -> 2 | N19: =TEXT(E19,"dd/mm/aaaa") -> 20/05/2026 | O19: =TEXT(K19,"dd/mm/aaaa") -> 20/05/2026 | P19: =COUNTIFS($R$2,"="&N19) -> 1 | Q19: =COUNTIFS($R$2,"="&O19) -> 1
A20: Flight scheduled | B20: E7 | C20: 734 | D20: E7 615 | E20: 46162.208 | F20: SLP-NLU | G20: --- | H20: 601A | I20: E7 615 | J20: NLU-MID | K20: 46162.229 | L20: F | M20: =VLOOKUP(L20,Data!$J$1:$K$13,2,0) -> 2 | N20: =TEXT(E20,"dd/mm/aaaa") -> 20/05/2026 | O20: =TEXT(K20,"dd/mm/aaaa") -> 20/05/2026 | P20: =COUNTIFS($R$2,"="&N20) -> 1 | Q20: =COUNTIFS($R$2,"="&O20) -> 1
A21: Flight scheduled | B21: XN | C21: E95 | D21: XN 1205 | E21: 46162.229 | F21: TIJ-NLU | G21: 3 | H21: 108B | I21: XN 1780 | J21: NLU-TQO | K21: 46162.368 | L21: J | M21: =VLOOKUP(L21,Data!$J$1:$K$13,2,0) -> 1 | N21: =TEXT(E21,"dd/mm/aaaa") -> 20/05/2026 | O21: =TEXT(K21,"dd/mm/aaaa") -> 20/05/2026 | P21: =COUNTIFS($R$2,"="&N21) -> 1 | Q21: =COUNTIFS($R$2,"="&O21) -> 1
A22: Flight scheduled | B22: CZ | C22: 772 | D22: CZ 2521 | E22: 46162.257 | F22: ANC-NLU | G22: --- | H22: 608 | I22: CZ 2522 | J22: NLU-PVG | K22: 46162.361 | L22: F | M22: =VLOOKUP(L22,Data!$J$1:$K$13,2,0) -> 2 | N22: =TEXT(E22,"dd/mm/aaaa") -> 20/05/2026 | O22: =TEXT(K22,"dd/mm/aaaa") -> 20/05/2026 | P22: =COUNTIFS($R$2,"="&N22) -> 1 | Q22: =COUNTIFS($R$2,"="&O22) -> 1
A23: Flight scheduled | B23: 5X | C23: 763 | D23: 5X 320 | E23: 46162.266 | F23: SDF-NLU | G23: --- | H23: 602A | I23: 5X 321 | J23: NLU-SDF | K23: 46162.818 | L23: F | M23: =VLOOKUP(L23,Data!$J$1:$K$13,2,0) -> 2 | N23: =TEXT(E23,"dd/mm/aaaa") -> 20/05/2026 | O23: =TEXT(K23,"dd/mm/aaaa") -> 20/05/2026 | P23: =COUNTIFS($R$2,"="&N23) -> 1 | Q23: =COUNTIFS($R$2,"="&O23) -> 1
A24: Flight activated | B24: AC | C24: 764 | D24: AC 7246 | E24: 46162.292 | F24: YYZ-NLU | G24: --- | H24: 601B | I24: AC 7246 | J24: NLU-GDL | K24: 46162.375 | L24: F | M24: =VLOOKUP(L24,Data!$J$1:$K$13,2,0) -> 2 | N24: =TEXT(E24,"dd/mm/aaaa") -> 20/05/2026 | O24: =TEXT(K24,"dd/mm/aaaa") -> 20/05/2026 | P24: =COUNTIFS($R$2,"="&N24) -> 1 | Q24: =COUNTIFS($R$2,"="&O24) -> 1
A25: Flight scheduled | B25: VB | C25: 32A | D25: VB 2272 | E25: 46162.312 | F25: CUN-NLU | G25: 1 | H25: 107B | I25: VB 2273 | J25: NLU-CUN | K25: 46162.354 | L25: J | M25: =VLOOKUP(L25,Data!$J$1:$K$13,2,0) -> 1 | N25: =TEXT(E25,"dd/mm/aaaa") -> 20/05/2026 | O25: =TEXT(K25,"dd/mm/aaaa") -> 20/05/2026 | P25: =COUNTIFS($R$2,"="&N25) -> 1 | Q25: =COUNTIFS($R$2,"="&O25) -> 1
A26: Flight scheduled | B26: VB | C26: 32A | D26: VB 7344 | E26: 46162.312 | F26: BJX-NLU | G26: 2 | H26: 502 | I26: VB 7344 | J26: NLU-CUU | K26: 46162.337 | L26: J | M26: =VLOOKUP(L26,Data!$J$1:$K$13,2,0) -> 1 | N26: =TEXT(E26,"dd/mm/aaaa") -> 20/05/2026 | O26: =TEXT(K26,"dd/mm/aaaa") -> 20/05/2026 | P26: =COUNTIFS($R$2,"="&N26) -> 1 | Q26: =COUNTIFS($R$2,"="&O26) -> 1
A27: Flight scheduled | B27: VB | C27: 320 | D27: VB 7332 | E27: 46162.312 | F27: MTY-NLU | G27: 1 | H27: 107A | I27: VB 7332 | J27: NLU-VSA | K27: 46162.337 | L27: J | M27: =VLOOKUP(L27,Data!$J$1:$K$13,2,0) -> 1 | N27: =TEXT(E27,"dd/mm/aaaa") -> 20/05/2026 | O27: =TEXT(K27,"dd/mm/aaaa") -> 20/05/2026 | P27: =COUNTIFS($R$2,"="&N27) -> 1 | Q27: =COUNTIFS($R$2,"="&O27) -> 1
A28: Flight scheduled | B28: VB | C28: 321 | D28: VB 7350 | E28: 46162.333 | F28: MID-NLU | G28: 2 | H28: 503 | I28: VB 7350 | J28: NLU-PVR | K28: 46162.361 | L28: J | M28: =VLOOKUP(L28,Data!$J$1:$K$13,2,0) -> 1 | N28: =TEXT(E28,"dd/mm/aaaa") -> 20/05/2026 | O28: =TEXT(K28,"dd/mm/aaaa") -> 20/05/2026 | P28: =COUNTIFS($R$2,"="&N28) -> 1 | Q28: =COUNTIFS($R$2,"="&O28) -> 1
A29: Flight scheduled | B29: AM | C29: E90 | D29: AM 2469 | E29: 46162.337 | F29: DGO-NLU | G29: 3 | H29: 110B | I29: AM 2436 | J29: NLU-CLQ | K29: 46162.369 | L29: J | M29: =VLOOKUP(L29,Data!$J$1:$K$13,2,0) -> 1 | N29: =TEXT(E29,"dd/mm/aaaa") -> 20/05/2026 | O29: =TEXT(K29,"dd/mm/aaaa") -> 20/05/2026 | P29: =COUNTIFS($R$2,"="&N29) -> 1 | Q29: =COUNTIFS($R$2,"="&O29) -> 1
A30: Flight scheduled | B30: W8 | C30: 76Y | D30: W8 952 | E30: 46162.354 | F30: CVG-NLU | G30: --- | H30: 601A | I30: W8 951 | J30: NLU-CVG | K30: 46162.833 | L30: F | M30: =VLOOKUP(L30,Data!$J$1:$K$13,2,0) -> 2 | N30: =TEXT(E30,"dd/mm/aaaa") -> 20/05/2026 | O30: =TEXT(K30,"dd/mm/aaaa") -> 20/05/2026 | P30: =COUNTIFS($R$2,"="&N30) -> 1 | Q30: =COUNTIFS($R$2,"="&O30) -> 1
A31: Flight scheduled | B31: 5Y | C31: 74Y/744 | D31: 5Y 8174 | E31: 46162.358 | F31: ANC-NLU | G31: --- | H31: 607 | I31: 5Y 8174 | J31: NLU-LAX | K31: 46162.441 | L31: F | M31: =VLOOKUP(L31,Data!$J$1:$K$13,2,0) -> 2 | N31: =TEXT(E31,"dd/mm/aaaa") -> 20/05/2026 | O31: =TEXT(K31,"dd/mm/aaaa") -> 20/05/2026 | P31: =COUNTIFS($R$2,"="&N31) -> 1 | Q31: =COUNTIFS($R$2,"="&O31) -> 1
A32: Flight scheduled | B32: VB | C32: 321 | D32: VB 9521 | E32: 46162.378 | F32: GDL-NLU | G32: 1 | H32: 115B | I32: VB 3676 | J32: NLU-ZIH | K32: 46162.41 | L32: J | M32: =VLOOKUP(L32,Data!$J$1:$K$13,2,0) -> 1 | N32: =TEXT(E32,"dd/mm/aaaa") -> 20/05/2026 | O32: =TEXT(K32,"dd/mm/aaaa") -> 20/05/2026 | P32: =COUNTIFS($R$2,"="&N32) -> 1 | Q32: =COUNTIFS($R$2,"="&O32) -> 1
A33: Flight scheduled | B33: XN | C33: 295 | D33: XN 1431 | E33: 46162.396 | F33: GDL-NLU | G33: 1 | H33: 108B | I33: XN 1700 | J33: NLU-CPE | K33: 46162.438 | L33: J | M33: =VLOOKUP(L33,Data!$J$1:$K$13,2,0) -> 1 | N33: =TEXT(E33,"dd/mm/aaaa") -> 20/05/2026 | O33: =TEXT(K33,"dd/mm/aaaa") -> 20/05/2026 | P33: =COUNTIFS($R$2,"="&N33) -> 1 | Q33: =COUNTIFS($R$2,"="&O33) -> 1
A34: Flight scheduled | B34: VB | C34: 32A | D34: VB 9223 | E34: 46162.403 | F34: PXM-NLU | G34: 2 | H34: 106B | I34: VB 9294 | J34: NLU-HUX | K34: 46162.434 | L34: J | M34: =VLOOKUP(L34,Data!$J$1:$K$13,2,0) -> 1 | N34: =TEXT(E34,"dd/mm/aaaa") -> 20/05/2026 | O34: =TEXT(K34,"dd/mm/aaaa") -> 20/05/2026 | P34: =COUNTIFS($R$2,"="&N34) -> 1 | Q34: =COUNTIFS($R$2,"="&O34) -> 1
A35: Flight scheduled | B35: XN | C35: 295 | D35: XN 1101 | E35: 46162.403 | F35: MTY-NLU | G35: 3 | H35: 108A | I35: XN 1142 | J35: NLU-CVM | K35: 46162.458 | L35: J | M35: =VLOOKUP(L35,Data!$J$1:$K$13,2,0) -> 1 | N35: =TEXT(E35,"dd/mm/aaaa") -> 20/05/2026 | O35: =TEXT(K35,"dd/mm/aaaa") -> 20/05/2026 | P35: =COUNTIFS($R$2,"="&N35) -> 1 | Q35: =COUNTIFS($R$2,"="&O35) -> 1
A36: Flight activated | B36: Y4 | C36: 320 | D36: Y4 1290 | E36: 46162.404 | F36: GDL-NLU | G36: 2 | H36: 109A | I36: Y4 3533 | J36: NLU-CUN | K36: 46162.463 | L36: J | M36: =VLOOKUP(L36,Data!$J$1:$K$13,2,0) -> 1 | N36: =TEXT(E36,"dd/mm/aaaa") -> 20/05/2026 | O36: =TEXT(K36,"dd/mm/aaaa") -> 20/05/2026 | P36: =COUNTIFS($R$2,"="&N36) -> 1 | Q36: =COUNTIFS($R$2,"="&O36) -> 1
A37: Flight scheduled | B37: VB | C37: 32Q | D37: VB 9401 | E37: 46162.41 | F37: MTY-NLU | G37: 2 | H37: 107A | I37: VB 9402 | J37: NLU-MTY | K37: 46162.441 | L37: J | M37: =VLOOKUP(L37,Data!$J$1:$K$13,2,0) -> 1 | N37: =TEXT(E37,"dd/mm/aaaa") -> 20/05/2026 | O37: =TEXT(K37,"dd/mm/aaaa") -> 20/05/2026 | P37: =COUNTIFS($R$2,"="&N37) -> 1 | Q37: =COUNTIFS($R$2,"="&O37) -> 1
A38: Flight scheduled | B38: AM | C38: E90 | D38: AM 2041 | E38: 46162.42 | F38: OAX-NLU | G38: 3 | H38: 110A | I38: AM 2042 | J38: NLU-OAX | K38: 46162.448 | L38: J | M38: =VLOOKUP(L38,Data!$J$1:$K$13,2,0) -> 1 | N38: =TEXT(E38,"dd/mm/aaaa") -> 20/05/2026 | O38: =TEXT(K38,"dd/mm/aaaa") -> 20/05/2026 | P38: =COUNTIFS($R$2,"="&N38) -> 1 | Q38: =COUNTIFS($R$2,"="&O38) -> 1
A39: Flight scheduled | B39: VB | C39: 321 | D39: VB 7428 | E39: 46162.427 | F39: TIJ-NLU | G39: 1 | H39: 106A | I39: VB 7428 | J39: NLU-TGZ | K39: 46162.455 | L39: J | M39: =VLOOKUP(L39,Data!$J$1:$K$13,2,0) -> 1 | N39: =TEXT(E39,"dd/mm/aaaa") -> 20/05/2026 | O39: =TEXT(K39,"dd/mm/aaaa") -> 20/05/2026 | P39: =COUNTIFS($R$2,"="&N39) -> 1 | Q39: =COUNTIFS($R$2,"="&O39) -> 1
A40: Flight scheduled | B40: VB | C40: 321 | D40: VB 7442 | E40: 46162.458 | F40: SJD-NLU | G40: 1 | H40: 107B | I40: VB 7442 | J40: NLU-CUN | K40: 46162.49 | L40: J | M40: =VLOOKUP(L40,Data!$J$1:$K$13,2,0) -> 1 | N40: =TEXT(E40,"dd/mm/aaaa") -> 20/05/2026 | O40: =TEXT(K40,"dd/mm/aaaa") -> 20/05/2026 | P40: =COUNTIFS($R$2,"="&N40) -> 1 | Q40: =COUNTIFS($R$2,"="&O40) -> 1
...

Sheet dashboard data

Sheet Pasajeros
A1: Num | B1: Status | C1: [Arr] Airline code | D1: Aircraft type | E1: [Arr] Flight Number | F1: [Arr] SIBT | G1: [Arr] Routing | H1: [Arr] Baggage Belts | I1: [Arr] Stand | J1: [Dep] Flight Designator | K1: [Dep] Routing | L1: [Dep] SOBT | M1: [Dep] Service Type | N1: Time frame | O1: Time Code llegadas | P1: Time frame | Q1: Time Code salidas | R1: feche llegada | S1: anteriores | T1: fecha salida | U1: posteriores
A2: =ROW(A1) -> 1 | B2: =IFERROR(INDEX('Pasajeros Pre'!$A$2:A4995,MATCH(ROW()-ROW($B$1),'Pasajeros Pre'!$O$2:$O$4995,0)),"") -> Last bag | C2: =IFERROR(INDEX('Pasajeros Pre'!$B$2:$B$195,MATCH(ROW()-ROW($A$1),'Pasajeros Pre'!$O$2:$O$195,0)),"") -> Mexicana de Aviación | D2: =IFERROR(INDEX('Pasajeros Pre'!$C$2:C4995,MATCH(ROW()-ROW($B$1),'Pasajeros Pre'!$O$2:$O$4995,0)),"") -> E95 | E2: =IFERROR(INDEX('Pasajeros Pre'!$D$2:D4995,MATCH(ROW()-ROW($B$1),'Pasajeros Pre'!$O$2:$O$4995,0)),"") -> XN 1765 | F2: =IFERROR(INDEX('Pasajeros Pre'!$E$2:E4995,MATCH(ROW()-ROW($B$1),'Pasajeros Pre'!$O$2:$O$4995,0)),"") -> 46160.833 | G2: =IFERROR(INDEX('Pasajeros Pre'!$F$2:F4995,MATCH(ROW()-ROW($B$1),'Pasajeros Pre'!$O$2:$O$4995,0)),"") -> Mérida | H2: =IFERROR(INDEX('Pasajeros Pre'!$G$2:G4995,MATCH(ROW()-ROW($B$1),'Pasajeros Pre'!$O$2:$O$4995,0)),"") -> 1 | I2: =IFERROR(INDEX('Pasajeros Pre'!$H$2:H4995,MATCH(ROW()-ROW($B$1),'Pasajeros Pre'!$O$2:$O$4995,0)),"") -> 108A | J2: =IFERROR(INDEX('Pasajeros Pre'!$I$2:I4995,MATCH(ROW()-ROW($B$1),'Pasajeros Pre'!$O$2:$O$4995,0)),"") -> XN 1430 | K2: =IFERROR(INDEX('Pasajeros Pre'!$J$2:J4995,MATCH(ROW()-ROW($B$1),'Pasajeros Pre'!$O$2:$O$4995,0)),"") -> Guadalajara | L2: =IFERROR(INDEX('Pasajeros Pre'!$K$2:K4995,MATCH(ROW()-ROW($B$1),'Pasajeros Pre'!$O$2:$O$4995,0)),"") -> 46162.271 | M2: =IFERROR(INDEX('Pasajeros Pre'!$L$2:L4995,MATCH(ROW()-ROW($B$1),'Pasajeros Pre'!$O$2:$O$4995,0)),"") -> J | N2: =ROUNDDOWN(HOUR(F2),1)+1 -> 21 | O2: =VLOOKUP(N2,'Time Chart'!$A$2:$D$25,4,0) -> 20:00 A 20:59 | P2: =ROUNDDOWN(HOUR(L2),1)+1 -> 7 | Q2: =VLOOKUP(P2,'Time Chart'!$A$2:$D$25,4,0) -> 06:00 A 06:59 | R2: =TEXT(F2,"dd/mm/aaaa") -> 18/05/2026 | S2: =COUNTIFS(Hoja1!$R$2,"="&R2) -> 0 | T2: =TEXT(L2,"dd/mm/aaaa") -> 20/05/2026 | U2: =COUNTIFS(Hoja1!$R$2,"="&T2) -> 1
A3: =ROW(A2) -> 2 | B3: =IFERROR(INDEX('Pasajeros Pre'!$A$2:A4996,MATCH(ROW()-ROW($B$1),'Pasajeros Pre'!$O$2:$O$4995,0)),"") -> Flight activated | C3: =IFERROR(INDEX('Pasajeros Pre'!$B$2:$B$195,MATCH(ROW()-ROW($A$1),'Pasajeros Pre'!$O$2:$O$195,0)),"") -> Viva | D3: =IFERROR(INDEX('Pasajeros Pre'!$C$2:C4996,MATCH(ROW()-ROW($B$1),'Pasajeros Pre'!$O$2:$O$4995,0)),"") -> 32Q | E3: =IFERROR(INDEX('Pasajeros Pre'!$D$2:D4996,MATCH(ROW()-ROW($B$1),'Pasajeros Pre'!$O$2:$O$4995,0)),"") -> VB 3677 | F3: =IFERROR(INDEX('Pasajeros Pre'!$E$2:E4996,MATCH(ROW()-ROW($B$1),'Pasajeros Pre'!$O$2:$O$4995,0)),"") -> 46161.524 | G3: =IFERROR(INDEX('Pasajeros Pre'!$F$2:F4996,MATCH(ROW()-ROW($B$1),'Pasajeros Pre'!$O$2:$O$4995,0)),"") -> Ixtapa Zihuatanejo | H3: =IFERROR(INDEX('Pasajeros Pre'!$G$2:G4996,MATCH(ROW()-ROW($B$1),'Pasajeros Pre'!$O$2:$O$4995,0)),"") -> 1 | I3: =IFERROR(INDEX('Pasajeros Pre'!$H$2:H4996,MATCH(ROW()-ROW($B$1),'Pasajeros Pre'!$O$2:$O$4995,0)),"") -> 132A | J3: =IFERROR(INDEX('Pasajeros Pre'!$I$2:I4996,MATCH(ROW()-ROW($B$1),'Pasajeros Pre'!$O$2:$O$4995,0)),"") -> VB 7382 | K3: =IFERROR(INDEX('Pasajeros Pre'!$J$2:J4996,MATCH(ROW()-ROW($B$1),'Pasajeros Pre'!$O$2:$O$4995,0)),"") -> Monterrey | L3: =IFERROR(INDEX('Pasajeros Pre'!$K$2:K4996,MATCH(ROW()-ROW($B$1),'Pasajeros Pre'!$O$2:$O$4995,0)),"") -> 46162.253 | M3: =IFERROR(INDEX('Pasajeros Pre'!$L$2:L4996,MATCH(ROW()-ROW($B$1),'Pasajeros Pre'!$O$2:$O$4995,0)),"") -> J | N3: =ROUNDDOWN(HOUR(F3),1)+1 -> 13 | O3: =VLOOKUP(N3,'Time Chart'!$A$2:$D$25,4,0) -> 12:00 A 12:59 | P3: =ROUNDDOWN(HOUR(L3),1)+1 -> 7 | Q3: =VLOOKUP(P3,'Time Chart'!$A$2:$D$25,4,0) -> 06:00 A 06:59 | R3: =TEXT(F3,"dd/mm/aaaa") -> 19/05/2026 | S3: =COUNTIFS(Hoja1!$R$2,"="&R3) -> 0 | T3: =TEXT(L3,"dd/mm/aaaa") -> 20/05/2026 | U3: =COUNTIFS(Hoja1!$R$2,"="&T3) -> 1
A4: =ROW(A3) -> 3 | B4: =IFERROR(INDEX('Pasajeros Pre'!$A$2:A4997,MATCH(ROW()-ROW($B$1),'Pasajeros Pre'!$O$2:$O$4995,0)),"") -> Flight activated | C4: =IFERROR(INDEX('Pasajeros Pre'!$B$2:$B$195,MATCH(ROW()-ROW($A$1),'Pasajeros Pre'!$O$2:$O$195,0)),"") -> Viva | D4: =IFERROR(INDEX('Pasajeros Pre'!$C$2:C4997,MATCH(ROW()-ROW($B$1),'Pasajeros Pre'!$O$2:$O$4995,0)),"") -> 32A | E4: =IFERROR(INDEX('Pasajeros Pre'!$D$2:D4997,MATCH(ROW()-ROW($B$1),'Pasajeros Pre'!$O$2:$O$4995,0)),"") -> VB 7370 | F4: =IFERROR(INDEX('Pasajeros Pre'!$E$2:E4997,MATCH(ROW()-ROW($B$1),'Pasajeros Pre'!$O$2:$O$4995,0)),"") -> 46161.622 | G4: =IFERROR(INDEX('Pasajeros Pre'!$F$2:F4997,MATCH(ROW()-ROW($B$1),'Pasajeros Pre'!$O$2:$O$4995,0)),"") -> La Paz | H4: =IFERROR(INDEX('Pasajeros Pre'!$G$2:G4997,MATCH(ROW()-ROW($B$1),'Pasajeros Pre'!$O$2:$O$4995,0)),"") -> 1 | I4: =IFERROR(INDEX('Pasajeros Pre'!$H$2:H4997,MATCH(ROW()-ROW($B$1),'Pasajeros Pre'!$O$2:$O$4995,0)),"") -> 107A | J4: =IFERROR(INDEX('Pasajeros Pre'!$I$2:I4997,MATCH(ROW()-ROW($B$1),'Pasajeros Pre'!$O$2:$O$4995,0)),"") -> VB 9222 | K4: =IFERROR(INDEX('Pasajeros Pre'!$J$2:J4997,MATCH(ROW()-ROW($B$1),'Pasajeros Pre'!$O$2:$O$4995,0)),"") -> Puerto Escondido | L4: =IFERROR(INDEX('Pasajeros Pre'!$K$2:K4997,MATCH(ROW()-ROW($B$1),'Pasajeros Pre'!$O$2:$O$4995,0)),"") -> 46162.274 | M4: =IFERROR(INDEX('Pasajeros Pre'!$L$2:L4997,MATCH(ROW()-ROW($B$1),'Pasajeros Pre'!$O$2:$O$4995,0)),"") -> J | N4: =ROUNDDOWN(HOUR(F4),1)+1 -> 15 | O4: =VLOOKUP(N4,'Time Chart'!$A$2:$D$25,4,0) -> 14:00 A 14:59 | P4: =ROUNDDOWN(HOUR(L4),1)+1 -> 7 | Q4: =VLOOKUP(P4,'Time Chart'!$A$2:$D$25,4,0) -> 06:00 A 06:59 | R4: =TEXT(F4,"dd/mm/aaaa") -> 19/05/2026 | S4: =COUNTIFS(Hoja1!$R$2,"="&R4) -> 0 | T4: =TEXT(L4,"dd/mm/aaaa") -> 20/05/2026 | U4: =COUNTIFS(Hoja1!$R$2,"="&T4) -> 1
A5: =ROW(A4) -> 4 | B5: =IFERROR(INDEX('Pasajeros Pre'!$A$2:A4998,MATCH(ROW()-ROW($B$1),'Pasajeros Pre'!$O$2:$O$4995,0)),"") -> Flight activated | C5: =IFERROR(INDEX('Pasajeros Pre'!$B$2:$B$195,MATCH(ROW()-ROW($A$1),'Pasajeros Pre'!$O$2:$O$195,0)),"") -> Aerus | D5: =IFERROR(INDEX('Pasajeros Pre'!$C$2:C4998,MATCH(ROW()-ROW($B$1),'Pasajeros Pre'!$O$2:$O$4995,0)),"") -> CNF | E5: =IFERROR(INDEX('Pasajeros Pre'!$D$2:D4998,MATCH(ROW()-ROW($B$1),'Pasajeros Pre'!$O$2:$O$4995,0)),"") -> ZV 361 | F5: =IFERROR(INDEX('Pasajeros Pre'!$E$2:E4998,MATCH(ROW()-ROW($B$1),'Pasajeros Pre'!$O$2:$O$4995,0)),"") -> 46161.712 | G5: =IFERROR(INDEX('Pasajeros Pre'!$F$2:F4998,MATCH(ROW()-ROW($B$1),'Pasajeros Pre'!$O$2:$O$4995,0)),"") -> Ciudad Victoria | H5: =IFERROR(INDEX('Pasajeros Pre'!$G$2:G4998,MATCH(ROW()-ROW($B$1),'Pasajeros Pre'!$O$2:$O$4995,0)),"") -> 1 | I5: =IFERROR(INDEX('Pasajeros Pre'!$H$2:H4998,MATCH(ROW()-ROW($B$1),'Pasajeros Pre'!$O$2:$O$4995,0)),"") -> 501 | J5: =IFERROR(INDEX('Pasajeros Pre'!$I$2:I4998,MATCH(ROW()-ROW($B$1),'Pasajeros Pre'!$O$2:$O$4995,0)),"") -> ZV 364 | K5: =IFERROR(INDEX('Pasajeros Pre'!$J$2:J4998,MATCH(ROW()-ROW($B$1),'Pasajeros Pre'!$O$2:$O$4995,0)),"") -> Ciudad Victoria | L5: =IFERROR(INDEX('Pasajeros Pre'!$K$2:K4998,MATCH(ROW()-ROW($B$1),'Pasajeros Pre'!$O$2:$O$4995,0)),"") -> 46162.25 | M5: =IFERROR(INDEX('Pasajeros Pre'!$L$2:L4998,MATCH(ROW()-ROW($B$1),'Pasajeros Pre'!$O$2:$O$4995,0)),"") -> J | N5: =ROUNDDOWN(HOUR(F5),1)+1 -> 18 | O5: =VLOOKUP(N5,'Time Chart'!$A$2:$D$25,4,0) -> 17:00 A 17:59 | P5: =ROUNDDOWN(HOUR(L5),1)+1 -> 7 | Q5: =VLOOKUP(P5,'Time Chart'!$A$2:$D$25,4,0) -> 06:00 A 06:59 | R5: =TEXT(F5,"dd/mm/aaaa") -> 19/05/2026 | S5: =COUNTIFS(Hoja1!$R$2,"="&R5) -> 0 | T5: =TEXT(L5,"dd/mm/aaaa") -> 20/05/2026 | U5: =COUNTIFS(Hoja1!$R$2,"="&T5) -> 1
A6: =ROW(A5) -> 5 | B6: =IFERROR(INDEX('Pasajeros Pre'!$A$2:A4999,MATCH(ROW()-ROW($B$1),'Pasajeros Pre'!$O$2:$O$4995,0)),"") -> Departed from previous airport | C6: =IFERROR(INDEX('Pasajeros Pre'!$B$2:$B$195,MATCH(ROW()-ROW($A$1),'Pasajeros Pre'!$O$2:$O$195,0)),"") -> Viva | D6: =IFERROR(INDEX('Pasajeros Pre'!$C$2:C4999,MATCH(ROW()-ROW($B$1),'Pasajeros Pre'!$O$2:$O$4995,0)),"") -> 32A | E6: =IFERROR(INDEX('Pasajeros Pre'!$D$2:D4999,MATCH(ROW()-ROW($B$1),'Pasajeros Pre'!$O$2:$O$4995,0)),"") -> VB 7435 | F6: =IFERROR(INDEX('Pasajeros Pre'!$E$2:E4999,MATCH(ROW()-ROW($B$1),'Pasajeros Pre'!$O$2:$O$4995,0)),"") -> 46161.844 | G6: =IFERROR(INDEX('Pasajeros Pre'!$F$2:F4999,MATCH(ROW()-ROW($B$1),'Pasajeros Pre'!$O$2:$O$4995,0)),"") -> Veracruz | H6: =IFERROR(INDEX('Pasajeros Pre'!$G$2:G4999,MATCH(ROW()-ROW($B$1),'Pasajeros Pre'!$O$2:$O$4995,0)),"") -> 2 | I6: =IFERROR(INDEX('Pasajeros Pre'!$H$2:H4999,MATCH(ROW()-ROW($B$1),'Pasajeros Pre'!$O$2:$O$4995,0)),"") -> 505 | J6: =IFERROR(INDEX('Pasajeros Pre'!$I$2:I4999,MATCH(ROW()-ROW($B$1),'Pasajeros Pre'!$O$2:$O$4995,0)),"") -> VB 9480 | K6: =IFERROR(INDEX('Pasajeros Pre'!$J$2:J4999,MATCH(ROW()-ROW($B$1),'Pasajeros Pre'!$O$2:$O$4995,0)),"") -> Ciudad Obregón | L6: =IFERROR(INDEX('Pasajeros Pre'!$K$2:K4999,MATCH(ROW()-ROW($B$1),'Pasajeros Pre'!$O$2:$O$4995,0)),"") -> 46162.288 | M6: =IFERROR(INDEX('Pasajeros Pre'!$L$2:L4999,MATCH(ROW()-ROW($B$1),'Pasajeros Pre'!$O$2:$O$4995,0)),"") -> J | N6: =ROUNDDOWN(HOUR(F6),1)+1 -> 21 | O6: =VLOOKUP(N6,'Time Chart'!$A$2:$D$25,4,0) -> 20:00 A 20:59 | P6: =ROUNDDOWN(HOUR(L6),1)+1 -> 7 | Q6: =VLOOKUP(P6,'Time Chart'!$A$2:$D$25,4,0) -> 06:00 A 06:59 | R6: =TEXT(F6,"dd/mm/aaaa") -> 19/05/2026 | S6: =COUNTIFS(Hoja1!$R$2,"="&R6) -> 0 | T6: =TEXT(L6,"dd/mm/aaaa") -> 20/05/2026 | U6: =COUNTIFS(Hoja1!$R$2,"="&T6) -> 1
A7: =ROW(A6) -> 6 | B7: =IFERROR(INDEX('Pasajeros Pre'!$A$2:A5000,MATCH(ROW()-ROW($B$1),'Pasajeros Pre'!$O$2:$O$4995,0)),"") -> Flight activated | C7: =IFERROR(INDEX('Pasajeros Pre'!$B$2:$B$195,MATCH(ROW()-ROW($A$1),'Pasajeros Pre'!$O$2:$O$195,0)),"") -> Volaris | D7: =IFERROR(INDEX('Pasajeros Pre'!$C$2:C5000,MATCH(ROW()-ROW($B$1),'Pasajeros Pre'!$O$2:$O$4995,0)),"") -> 320 | E7: =IFERROR(INDEX('Pasajeros Pre'!$D$2:D5000,MATCH(ROW()-ROW($B$1),'Pasajeros Pre'!$O$2:$O$4995,0)),"") -> Y4 7171 | F7: =IFERROR(INDEX('Pasajeros Pre'!$E$2:E5000,MATCH(ROW()-ROW($B$1),'Pasajeros Pre'!$O$2:$O$4995,0)),"") -> 46161.849 | G7: =IFERROR(INDEX('Pasajeros Pre'!$F$2:F5000,MATCH(ROW()-ROW($B$1),'Pasajeros Pre'!$O$2:$O$4995,0)),"") -> La Paz | H7: =IFERROR(INDEX('Pasajeros Pre'!$G$2:G5000,MATCH(ROW()-ROW($B$1),'Pasajeros Pre'!$O$2:$O$4995,0)),"") -> 1 | I7: =IFERROR(INDEX('Pasajeros Pre'!$H$2:H5000,MATCH(ROW()-ROW($B$1),'Pasajeros Pre'!$O$2:$O$4995,0)),"") -> 109B | J7: =IFERROR(INDEX('Pasajeros Pre'!$I$2:I5000,MATCH(ROW()-ROW($B$1),'Pasajeros Pre'!$O$2:$O$4995,0)),"") -> Y4 1291 | K7: =IFERROR(INDEX('Pasajeros Pre'!$J$2:J5000,MATCH(ROW()-ROW($B$1),'Pasajeros Pre'!$O$2:$O$4995,0)),"") -> Guadalajara | L7: =IFERROR(INDEX('Pasajeros Pre'!$K$2:K5000,MATCH(ROW()-ROW($B$1),'Pasajeros Pre'!$O$2:$O$4995,0)),"") -> 46162.271 | M7: =IFERROR(INDEX('Pasajeros Pre'!$L$2:L5000,MATCH(ROW()-ROW($B$1),'Pasajeros Pre'!$O$2:$O$4995,0)),"") -> J | N7: =ROUNDDOWN(HOUR(F7),1)+1 -> 21 | O7: =VLOOKUP(N7,'Time Chart'!$A$2:$D$25,4,0) -> 20:00 A 20:59 | P7: =ROUNDDOWN(HOUR(L7),1)+1 -> 7 | Q7: =VLOOKUP(P7,'Time Chart'!$A$2:$D$25,4,0) -> 06:00 A 06:59 | R7: =TEXT(F7,"dd/mm/aaaa") -> 19/05/2026 | S7: =COUNTIFS(Hoja1!$R$2,"="&R7) -> 0 | T7: =TEXT(L7,"dd/mm/aaaa") -> 20/05/2026 | U7: =COUNTIFS(Hoja1!$R$2,"="&T7) -> 1
A8: =ROW(A7) -> 7 | B8: =IFERROR(INDEX('Pasajeros Pre'!$A$2:A5001,MATCH(ROW()-ROW($B$1),'Pasajeros Pre'!$O$2:$O$4995,0)),"") -> Flight activated | C8: =IFERROR(INDEX('Pasajeros Pre'!$B$2:$B$195,MATCH(ROW()-ROW($A$1),'Pasajeros Pre'!$O$2:$O$195,0)),"") -> Volaris | D8: =IFERROR(INDEX('Pasajeros Pre'!$C$2:C5001,MATCH(ROW()-ROW($B$1),'Pasajeros Pre'!$O$2:$O$4995,0)),"") -> 32N | E8: =IFERROR(INDEX('Pasajeros Pre'!$D$2:D5001,MATCH(ROW()-ROW($B$1),'Pasajeros Pre'!$O$2:$O$4995,0)),"") -> Y4 1292 | F8: =IFERROR(INDEX('Pasajeros Pre'!$E$2:E5001,MATCH(ROW()-ROW($B$1),'Pasajeros Pre'!$O$2:$O$4995,0)),"") -> 46161.852 | G8: =IFERROR(INDEX('Pasajeros Pre'!$F$2:F5001,MATCH(ROW()-ROW($B$1),'Pasajeros Pre'!$O$2:$O$4995,0)),"") -> Guadalajara | H8: =IFERROR(INDEX('Pasajeros Pre'!$G$2:G5001,MATCH(ROW()-ROW($B$1),'Pasajeros Pre'!$O$2:$O$4995,0)),"") -> 1 | I8: =IFERROR(INDEX('Pasajeros Pre'!$H$2:H5001,MATCH(ROW()-ROW($B$1),'Pasajeros Pre'!$O$2:$O$4995,0)),"") -> 109A | J8: =IFERROR(INDEX('Pasajeros Pre'!$I$2:I5001,MATCH(ROW()-ROW($B$1),'Pasajeros Pre'!$O$2:$O$4995,0)),"") -> Y4 3960 | K8: =IFERROR(INDEX('Pasajeros Pre'!$J$2:J5001,MATCH(ROW()-ROW($B$1),'Pasajeros Pre'!$O$2:$O$4995,0)),"") -> Bogotá | L8: =IFERROR(INDEX('Pasajeros Pre'!$K$2:K5001,MATCH(ROW()-ROW($B$1),'Pasajeros Pre'!$O$2:$O$4995,0)),"") -> 46162.025 | M8: =IFERROR(INDEX('Pasajeros Pre'!$L$2:L5001,MATCH(ROW()-ROW($B$1),'Pasajeros Pre'!$O$2:$O$4995,0)),"") -> J | N8: =ROUNDDOWN(HOUR(F8),1)+1 -> 21 | O8: =VLOOKUP(N8,'Time Chart'!$A$2:$D$25,4,0) -> 20:00 A 20:59 | P8: =ROUNDDOWN(HOUR(L8),1)+1 -> 1 | Q8: =VLOOKUP(P8,'Time Chart'!$A$2:$D$25,4,0) -> 00:00 A 00:59 | R8: =TEXT(F8,"dd/mm/aaaa") -> 19/05/2026 | S8: =COUNTIFS(Hoja1!$R$2,"="&R8) -> 0 | T8: =TEXT(L8,"dd/mm/aaaa") -> 20/05/2026 | U8: =COUNTIFS(Hoja1!$R$2,"="&T8) -> 1
A9: =ROW(A8) -> 8 | B9: =IFERROR(INDEX('Pasajeros Pre'!$A$2:A5002,MATCH(ROW()-ROW($B$1),'Pasajeros Pre'!$O$2:$O$4995,0)),"") -> Flight activated | C9: =IFERROR(INDEX('Pasajeros Pre'!$B$2:$B$195,MATCH(ROW()-ROW($A$1),'Pasajeros Pre'!$O$2:$O$195,0)),"") -> Aeromexico | D9: =IFERROR(INDEX('Pasajeros Pre'!$C$2:C5002,MATCH(ROW()-ROW($B$1),'Pasajeros Pre'!$O$2:$O$4995,0)),"") -> E90 | E9: =IFERROR(INDEX('Pasajeros Pre'!$D$2:D5002,MATCH(ROW()-ROW($B$1),'Pasajeros Pre'!$O$2:$O$4995,0)),"") -> AM 871 | F9: =IFERROR(INDEX('Pasajeros Pre'!$E$2:E5002,MATCH(ROW()-ROW($B$1),'Pasajeros Pre'!$O$2:$O$4995,0)),"") -> 46161.863 | G9: =IFERROR(INDEX('Pasajeros Pre'!$F$2:F5002,MATCH(ROW()-ROW($B$1),'Pasajeros Pre'!$O$2:$O$4995,0)),"") -> Veracruz | H9: =IFERROR(INDEX('Pasajeros Pre'!$G$2:G5002,MATCH(ROW()-ROW($B$1),'Pasajeros Pre'!$O$2:$O$4995,0)),"") -> --- | I9: =IFERROR(INDEX('Pasajeros Pre'!$H$2:H5002,MATCH(ROW()-ROW($B$1),'Pasajeros Pre'!$O$2:$O$4995,0)),"") -> 111A | J9: =IFERROR(INDEX('Pasajeros Pre'!$I$2:I5002,MATCH(ROW()-ROW($B$1),'Pasajeros Pre'!$O$2:$O$4995,0)),"") -> AM 880 | K9: =IFERROR(INDEX('Pasajeros Pre'!$J$2:J5002,MATCH(ROW()-ROW($B$1),'Pasajeros Pre'!$O$2:$O$4995,0)),"") -> Puerto Vallarta | L9: =IFERROR(INDEX('Pasajeros Pre'!$K$2:K5002,MATCH(ROW()-ROW($B$1),'Pasajeros Pre'!$O$2:$O$4995,0)),"") -> 46162.604 | M9: =IFERROR(INDEX('Pasajeros Pre'!$L$2:L5002,MATCH(ROW()-ROW($B$1),'Pasajeros Pre'!$O$2:$O$4995,0)),"") -> J | N9: =ROUNDDOWN(HOUR(F9),1)+1 -> 21 | O9: =VLOOKUP(N9,'Time Chart'!$A$2:$D$25,4,0) -> 20:00 A 20:59 | P9: =ROUNDDOWN(HOUR(L9),1)+1 -> 15 | Q9: =VLOOKUP(P9,'Time Chart'!$A$2:$D$25,4,0) -> 14:00 A 14:59 | R9: =TEXT(F9,"dd/mm/aaaa") -> 19/05/2026 | S9: =COUNTIFS(Hoja1!$R$2,"="&R9) -> 0 | T9: =TEXT(L9,"dd/mm/aaaa") -> 20/05/2026 | U9: =COUNTIFS(Hoja1!$R$2,"="&T9) -> 1
A10: =ROW(A9) -> 9 | B10: =IFERROR(INDEX('Pasajeros Pre'!$A$2:A5003,MATCH(ROW()-ROW($B$1),'Pasajeros Pre'!$O$2:$O$4995,0)),"") -> Flight activated | C10: =IFERROR(INDEX('Pasajeros Pre'!$B$2:$B$195,MATCH(ROW()-ROW($A$1),'Pasajeros Pre'!$O$2:$O$195,0)),"") -> Viva | D10: =IFERROR(INDEX('Pasajeros Pre'!$C$2:C5003,MATCH(ROW()-ROW($B$1),'Pasajeros Pre'!$O$2:$O$4995,0)),"") -> 32N | E10: =IFERROR(INDEX('Pasajeros Pre'!$D$2:D5003,MATCH(ROW()-ROW($B$1),'Pasajeros Pre'!$O$2:$O$4995,0)),"") -> VB 9233 | F10: =IFERROR(INDEX('Pasajeros Pre'!$E$2:E5003,MATCH(ROW()-ROW($B$1),'Pasajeros Pre'!$O$2:$O$4995,0)),"") -> 46161.944 | G10: =IFERROR(INDEX('Pasajeros Pre'!$F$2:F5003,MATCH(ROW()-ROW($B$1),'Pasajeros Pre'!$O$2:$O$4995,0)),"") -> Mazatlán | H10: =IFERROR(INDEX('Pasajeros Pre'!$G$2:G5003,MATCH(ROW()-ROW($B$1),'Pasajeros Pre'!$O$2:$O$4995,0)),"") -> 1 | I10: =IFERROR(INDEX('Pasajeros Pre'!$H$2:H5003,MATCH(ROW()-ROW($B$1),'Pasajeros Pre'!$O$2:$O$4995,0)),"") -> 503 | J10: =IFERROR(INDEX('Pasajeros Pre'!$I$2:I5003,MATCH(ROW()-ROW($B$1),'Pasajeros Pre'!$O$2:$O$4995,0)),"") -> VB 5069 | K10: =IFERROR(INDEX('Pasajeros Pre'!$J$2:J5003,MATCH(ROW()-ROW($B$1),'Pasajeros Pre'!$O$2:$O$4995,0)),"") -> Tijuana | L10: =IFERROR(INDEX('Pasajeros Pre'!$K$2:K5003,MATCH(ROW()-ROW($B$1),'Pasajeros Pre'!$O$2:$O$4995,0)),"") -> 46162.25 | M10: =IFERROR(INDEX('Pasajeros Pre'!$L$2:L5003,MATCH(ROW()-ROW($B$1),'Pasajeros Pre'!$O$2:$O$4995,0)),"") -> J | N10: =ROUNDDOWN(HOUR(F10),1)+1 -> 23 | O10: =VLOOKUP(N10,'Time Chart'!$A$2:$D$25,4,0) -> 22:00 A 22:59 | P10: =ROUNDDOWN(HOUR(L10),1)+1 -> 7 | Q10: =VLOOKUP(P10,'Time Chart'!$A$2:$D$25,4,0) -> 06:00 A 06:59 | R10: =TEXT(F10,"dd/mm/aaaa") -> 19/05/2026 | S10: =COUNTIFS(Hoja1!$R$2,"="&R10) -> 0 | T10: =TEXT(L10,"dd/mm/aaaa") -> 20/05/2026 | U10: =COUNTIFS(Hoja1!$R$2,"="&T10) -> 1
A11: =ROW(A10) -> 10 | B11: =IFERROR(INDEX('Pasajeros Pre'!$A$2:A5004,MATCH(ROW()-ROW($B$1),'Pasajeros Pre'!$O$2:$O$4995,0)),"") -> Flight scheduled | C11: =IFERROR(INDEX('Pasajeros Pre'!$B$2:$B$195,MATCH(ROW()-ROW($A$1),'Pasajeros Pre'!$O$2:$O$195,0)),"") -> Mexicana de Aviación | D11: =IFERROR(INDEX('Pasajeros Pre'!$C$2:C5004,MATCH(ROW()-ROW($B$1),'Pasajeros Pre'!$O$2:$O$4995,0)),"") -> 295 | E11: =IFERROR(INDEX('Pasajeros Pre'!$D$2:D5004,MATCH(ROW()-ROW($B$1),'Pasajeros Pre'!$O$2:$O$4995,0)),"") -> XN 1107 | F11: =IFERROR(INDEX('Pasajeros Pre'!$E$2:E5004,MATCH(ROW()-ROW($B$1),'Pasajeros Pre'!$O$2:$O$4995,0)),"") -> 46161.955 | G11: =IFERROR(INDEX('Pasajeros Pre'!$F$2:F5004,MATCH(ROW()-ROW($B$1),'Pasajeros Pre'!$O$2:$O$4995,0)),"") -> Monterrey | H11: =IFERROR(INDEX('Pasajeros Pre'!$G$2:G5004,MATCH(ROW()-ROW($B$1),'Pasajeros Pre'!$O$2:$O$4995,0)),"") -> 3 | I11: =IFERROR(INDEX('Pasajeros Pre'!$H$2:H5004,MATCH(ROW()-ROW($B$1),'Pasajeros Pre'!$O$2:$O$4995,0)),"") -> 112B | J11: =IFERROR(INDEX('Pasajeros Pre'!$I$2:I5004,MATCH(ROW()-ROW($B$1),'Pasajeros Pre'!$O$2:$O$4995,0)),"") -> XN 1100 | K11: =IFERROR(INDEX('Pasajeros Pre'!$J$2:J5004,MATCH(ROW()-ROW($B$1),'Pasajeros Pre'!$O$2:$O$4995,0)),"") -> Monterrey | L11: =IFERROR(INDEX('Pasajeros Pre'!$K$2:K5004,MATCH(ROW()-ROW($B$1),'Pasajeros Pre'!$O$2:$O$4995,0)),"") -> 46162.25 | M11: =IFERROR(INDEX('Pasajeros Pre'!$L$2:L5004,MATCH(ROW()-ROW($B$1),'Pasajeros Pre'!$O$2:$O$4995,0)),"") -> J | N11: =ROUNDDOWN(HOUR(F11),1)+1 -> 23 | O11: =VLOOKUP(N11,'Time Chart'!$A$2:$D$25,4,0) -> 22:00 A 22:59 | P11: =ROUNDDOWN(HOUR(L11),1)+1 -> 7 | Q11: =VLOOKUP(P11,'Time Chart'!$A$2:$D$25,4,0) -> 06:00 A 06:59 | R11: =TEXT(F11,"dd/mm/aaaa") -> 19/05/2026 | S11: =COUNTIFS(Hoja1!$R$2,"="&R11) -> 0 | T11: =TEXT(L11,"dd/mm/aaaa") -> 20/05/2026 | U11: =COUNTIFS(Hoja1!$R$2,"="&T11) -> 1
A12: =ROW(A11) -> 11 | B12: =IFERROR(INDEX('Pasajeros Pre'!$A$2:A5005,MATCH(ROW()-ROW($B$1),'Pasajeros Pre'!$O$2:$O$4995,0)),"") -> Flight scheduled | C12: =IFERROR(INDEX('Pasajeros Pre'!$B$2:$B$195,MATCH(ROW()-ROW($A$1),'Pasajeros Pre'!$O$2:$O$195,0)),"") -> Mexicana de Aviación | D12: =IFERROR(INDEX('Pasajeros Pre'!$C$2:C5005,MATCH(ROW()-ROW($B$1),'Pasajeros Pre'!$O$2:$O$4995,0)),"") -> 295 | E12: =IFERROR(INDEX('Pasajeros Pre'!$D$2:D5005,MATCH(ROW()-ROW($B$1),'Pasajeros Pre'!$O$2:$O$4995,0)),"") -> XN 1437 | F12: =IFERROR(INDEX('Pasajeros Pre'!$E$2:E5005,MATCH(ROW()-ROW($B$1),'Pasajeros Pre'!$O$2:$O$4995,0)),"") -> 46161.958 | G12: =IFERROR(INDEX('Pasajeros Pre'!$F$2:F5005,MATCH(ROW()-ROW($B$1),'Pasajeros Pre'!$O$2:$O$4995,0)),"") -> Guadalajara | H12: =IFERROR(INDEX('Pasajeros Pre'!$G$2:G5005,MATCH(ROW()-ROW($B$1),'Pasajeros Pre'!$O$2:$O$4995,0)),"") -> 3 | I12: =IFERROR(INDEX('Pasajeros Pre'!$H$2:H5005,MATCH(ROW()-ROW($B$1),'Pasajeros Pre'!$O$2:$O$4995,0)),"") -> 108A | J12: =IFERROR(INDEX('Pasajeros Pre'!$I$2:I5005,MATCH(ROW()-ROW($B$1),'Pasajeros Pre'!$O$2:$O$4995,0)),"") -> XN 1760 | K12: =IFERROR(INDEX('Pasajeros Pre'!$J$2:J5005,MATCH(ROW()-ROW($B$1),'Pasajeros Pre'!$O$2:$O$4995,0)),"") -> Mérida | L12: =IFERROR(INDEX('Pasajeros Pre'!$K$2:K5005,MATCH(ROW()-ROW($B$1),'Pasajeros Pre'!$O$2:$O$4995,0)),"") -> 46162.285 | M12: =IFERROR(INDEX('Pasajeros Pre'!$L$2:L5005,MATCH(ROW()-ROW($B$1),'Pasajeros Pre'!$O$2:$O$4995,0)),"") -> J | N12: =ROUNDDOWN(HOUR(F12),1)+1 -> 24 | O12: =VLOOKUP(N12,'Time Chart'!$A$2:$D$25,4,0) -> 23:00 A 23:59 | P12: =ROUNDDOWN(HOUR(L12),1)+1 -> 7 | Q12: =VLOOKUP(P12,'Time Chart'!$A$2:$D$25,4,0) -> 06:00 A 06:59 | R12: =TEXT(F12,"dd/mm/aaaa") -> 19/05/2026 | S12: =COUNTIFS(Hoja1!$R$2,"="&R12) -> 0 | T12: =TEXT(L12,"dd/mm/aaaa") -> 20/05/2026 | U12: =COUNTIFS(Hoja1!$R$2,"="&T12) -> 1
A13: =ROW(A12) -> 12 | B13: =IFERROR(INDEX('Pasajeros Pre'!$A$2:A5006,MATCH(ROW()-ROW($B$1),'Pasajeros Pre'!$O$2:$O$4995,0)),"") -> Flight activated | C13: =IFERROR(INDEX('Pasajeros Pre'!$B$2:$B$195,MATCH(ROW()-ROW($A$1),'Pasajeros Pre'!$O$2:$O$195,0)),"") -> Viva | D13: =IFERROR(INDEX('Pasajeros Pre'!$C$2:C5006,MATCH(ROW()-ROW($B$1),'Pasajeros Pre'!$O$2:$O$4995,0)),"") -> 321 | E13: =IFERROR(INDEX('Pasajeros Pre'!$D$2:D5006,MATCH(ROW()-ROW($B$1),'Pasajeros Pre'!$O$2:$O$4995,0)),"") -> VB 2288 | F13: =IFERROR(INDEX('Pasajeros Pre'!$E$2:E5006,MATCH(ROW()-ROW($B$1),'Pasajeros Pre'!$O$2:$O$4995,0)),"") -> 46161.962 | G13: =IFERROR(INDEX('Pasajeros Pre'!$F$2:F5006,MATCH(ROW()-ROW($B$1),'Pasajeros Pre'!$O$2:$O$4995,0)),"") -> Cancún | H13: =IFERROR(INDEX('Pasajeros Pre'!$G$2:G5006,MATCH(ROW()-ROW($B$1),'Pasajeros Pre'!$O$2:$O$4995,0)),"") -> 2 | I13: =IFERROR(INDEX('Pasajeros Pre'!$H$2:H5006,MATCH(ROW()-ROW($B$1),'Pasajeros Pre'!$O$2:$O$4995,0)),"") -> 502 | J13: =IFERROR(INDEX('Pasajeros Pre'!$I$2:I5006,MATCH(ROW()-ROW($B$1),'Pasajeros Pre'!$O$2:$O$4995,0)),"") -> VB 2281 | K13: =IFERROR(INDEX('Pasajeros Pre'!$J$2:J5006,MATCH(ROW()-ROW($B$1),'Pasajeros Pre'!$O$2:$O$4995,0)),"") -> Cancún | L13: =IFERROR(INDEX('Pasajeros Pre'!$K$2:K5006,MATCH(ROW()-ROW($B$1),'Pasajeros Pre'!$O$2:$O$4995,0)),"") -> 46162.264 | M13: =IFERROR(INDEX('Pasajeros Pre'!$L$2:L5006,MATCH(ROW()-ROW($B$1),'Pasajeros Pre'!$O$2:$O$4995,0)),"") -> J | N13: =ROUNDDOWN(HOUR(F13),1)+1 -> 24 | O13: =VLOOKUP(N13,'Time Chart'!$A$2:$D$25,4,0) -> 23:00 A 23:59 | P13: =ROUNDDOWN(HOUR(L13),1)+1 -> 7 | Q13: =VLOOKUP(P13,'Time Chart'!$A$2:$D$25,4,0) -> 06:00 A 06:59 | R13: =TEXT(F13,"dd/mm/aaaa") -> 19/05/2026 | S13: =COUNTIFS(Hoja1!$R$2,"="&R13) -> 0 | T13: =TEXT(L13,"dd/mm/aaaa") -> 20/05/2026 | U13: =COUNTIFS(Hoja1!$R$2,"="&T13) -> 1
... A54: =ROW(A53) -> 53 | B54: =IFERROR(INDEX('Pasajeros Pre'!$A$2:A5047,MATCH(ROW()-ROW($B$1),'Pasajeros Pre'!$O$2:$O$4995,0)),"") -> Flight scheduled | C54: =IFERROR(INDEX('Pasajeros Pre'!$B$2:$B$195,MATCH(ROW()-ROW($A$1),'Pasajeros Pre'!$O$2:$O$195,0)),"") -> Volaris | D54: =IFERROR(INDEX('Pasajeros Pre'!$C$2:C5047,MATCH(ROW()-ROW($B$1),'Pasajeros Pre'!$O$2:$O$4995,0)),"") -> 32N | E54: =IFERROR(INDEX('Pasajeros Pre'!$D$2:D5047,MATCH(ROW()-ROW($B$1),'Pasajeros Pre'!$O$2:$O$4995,0)),"") -> Y4 3532 | F54: =IFERROR(INDEX('Pasajeros Pre'!$E$2:E5047,MATCH(ROW()-ROW($B$1),'Pasajeros Pre'!$O$2:$O$4995,0)),"") -> 46162.68 | G54: =IFERROR(INDEX('Pasajeros Pre'!$F$2:F5047,MATCH(ROW()-ROW($B$1),'Pasajeros Pre'!$O$2:$O$4995,0)),"") -> Cancún | H54: =IFERROR(INDEX('Pasajeros Pre'!$G$2:G5047,MATCH(ROW()-ROW($B$1),'Pasajeros Pre'!$O$2:$O$4995,0)),"") -> 2 | I54: =IFERROR(INDEX('Pasajeros Pre'!$H$2:H5047,MATCH(ROW()-ROW($B$1),'Pasajeros Pre'!$O$2:$O$4995,0)),"") -> 109A | J54: =IFERROR(INDEX('Pasajeros Pre'!$I$2:I5047,MATCH(ROW()-ROW($B$1),'Pasajeros Pre'!$O$2:$O$4995,0)),"") -> Y4 1293 | K54: =IFERROR(INDEX('Pasajeros Pre'!$J$2:J5047,MATCH(ROW()-ROW($B$1),'Pasajeros Pre'!$O$2:$O$4995,0)),"") -> Guadalajara | L54: =IFERROR(INDEX('Pasajeros Pre'!$K$2:K5047,MATCH(ROW()-ROW($B$1),'Pasajeros Pre'!$O$2:$O$4995,0)),"") -> 46162.719 | M54: =IFERROR(INDEX('Pasajeros Pre'!$L$2:L5047,MATCH(ROW()-ROW($B$1),'Pasajeros Pre'!$O$2:$O$4995,0)),"") -> J | N54: =ROUNDDOWN(HOUR(F54),1)+1 -> 17 | O54: =VLOOKUP(N54,'Time Chart'!$A$2:$D$25,4,0) -> 16:00 A 16:59 | P54: =ROUNDDOWN(HOUR(L54),1)+1 -> 18 | Q54: =VLOOKUP(P54,'Time Chart'!$A$2:$D$25,4,0) -> 17:00 A 17:59 | R54: =TEXT(F54,"dd/mm/aaaa") -> 20/05/2026 | S54: =COUNTIFS(Hoja1!$R$2,"="&R54) -> 1 | T54: =TEXT(L54,"dd/mm/aaaa") -> 20/05/2026 | U54: =COUNTIFS(Hoja1!$R$2,"="&T54) -> 1
A55: =ROW(A54) -> 54 | B55: =IFERROR(INDEX('Pasajeros Pre'!$A$2:A5048,MATCH(ROW()-ROW($B$1),'Pasajeros Pre'!$O$2:$O$4995,0)),"") -> Flight scheduled | C55: =IFERROR(INDEX('Pasajeros Pre'!$B$2:$B$300,MATCH(ROW()-ROW($A$1),'Pasajeros Pre'!$O$2:$O$195,0)),"") -> Viva | D55: =IFERROR(INDEX('Pasajeros Pre'!$C$2:C5048,MATCH(ROW()-ROW($B$1),'Pasajeros Pre'!$O$2:$O$4995,0)),"") -> 32A | E55: =IFERROR(INDEX('Pasajeros Pre'!$D$2:D5048,MATCH(ROW()-ROW($B$1),'Pasajeros Pre'!$O$2:$O$4995,0)),"") -> VB 9533 | F55: =IFERROR(INDEX('Pasajeros Pre'!$E$2:E5048,MATCH(ROW()-ROW($B$1),'Pasajeros Pre'!$O$2:$O$4995,0)),"") -> 46162.684 | G55: =IFERROR(INDEX('Pasajeros Pre'!$F$2:F5048,MATCH(ROW()-ROW($B$1),'Pasajeros Pre'!$O$2:$O$4995,0)),"") -> Matamoros | H55: =IFERROR(INDEX('Pasajeros Pre'!$G$2:G5048,MATCH(ROW()-ROW($B$1),'Pasajeros Pre'!$O$2:$O$4995,0)),"") -> 1 | I55: =IFERROR(INDEX('Pasajeros Pre'!$H$2:H5048,MATCH(ROW()-ROW($B$1),'Pasajeros Pre'!$O$2:$O$4995,0)),"") -> 505 | J55: =IFERROR(INDEX('Pasajeros Pre'!$I$2:I5048,MATCH(ROW()-ROW($B$1),'Pasajeros Pre'!$O$2:$O$4995,0)),"") -> VB 9522 | K55: =IFERROR(INDEX('Pasajeros Pre'!$J$2:J5048,MATCH(ROW()-ROW($B$1),'Pasajeros Pre'!$O$2:$O$4995,0)),"") -> Guadalajara | L55: =IFERROR(INDEX('Pasajeros Pre'!$K$2:K5048,MATCH(ROW()-ROW($B$1),'Pasajeros Pre'!$O$2:$O$4995,0)),"") -> 46162.708 | M55: =IFERROR(INDEX('Pasajeros Pre'!$L$2:L5048,MATCH(ROW()-ROW($B$1),'Pasajeros Pre'!$O$2:$O$4995,0)),"") -> J | N55: =ROUNDDOWN(HOUR(F55),1)+1 -> 17 | O55: =VLOOKUP(N55,'Time Chart'!$A$2:$D$25,4,0) -> 16:00 A 16:59 | P55: =ROUNDDOWN(HOUR(L55),1)+1 -> 18 | Q55: =VLOOKUP(P55,'Time Chart'!$A$2:$D$25,4,0) -> 17:00 A 17:59 | R55: =TEXT(F55,"dd/mm/aaaa") -> 20/05/2026 | S55: =COUNTIFS(Hoja1!$R$2,"="&R55) -> 1 | T55: =TEXT(L55,"dd/mm/aaaa") -> 20/05/2026 | U55: =COUNTIFS(Hoja1!$R$2,"="&T55) -> 1
A56: =ROW(A55) -> 55 | B56: =IFERROR(INDEX('Pasajeros Pre'!$A$2:A5049,MATCH(ROW()-ROW($B$1),'Pasajeros Pre'!$O$2:$O$4995,0)),"") -> Flight scheduled | C56: =IFERROR(INDEX('Pasajeros Pre'!$B$2:$B$195,MATCH(ROW()-ROW($A$1),'Pasajeros Pre'!$O$2:$O$195,0)),"") -> Volaris | D56: =IFERROR(INDEX('Pasajeros Pre'!$C$2:C5049,MATCH(ROW()-ROW($B$1),'Pasajeros Pre'!$O$2:$O$4995,0)),"") -> 32N | E56: =IFERROR(INDEX('Pasajeros Pre'!$D$2:D5049,MATCH(ROW()-ROW($B$1),'Pasajeros Pre'!$O$2:$O$4995,0)),"") -> Y4 7121 | F56: =IFERROR(INDEX('Pasajeros Pre'!$E$2:E5049,MATCH(ROW()-ROW($B$1),'Pasajeros Pre'!$O$2:$O$4995,0)),"") -> 46162.708 | G56: =IFERROR(INDEX('Pasajeros Pre'!$F$2:F5049,MATCH(ROW()-ROW($B$1),'Pasajeros Pre'!$O$2:$O$4995,0)),"") -> Los Cabos | H56: =IFERROR(INDEX('Pasajeros Pre'!$G$2:G5049,MATCH(ROW()-ROW($B$1),'Pasajeros Pre'!$O$2:$O$4995,0)),"") -> 2 | I56: =IFERROR(INDEX('Pasajeros Pre'!$H$2:H5049,MATCH(ROW()-ROW($B$1),'Pasajeros Pre'!$O$2:$O$4995,0)),"") -> 109B | J56: =IFERROR(INDEX('Pasajeros Pre'!$I$2:I5049,MATCH(ROW()-ROW($B$1),'Pasajeros Pre'!$O$2:$O$4995,0)),"") -> Y4 7110 | K56: =IFERROR(INDEX('Pasajeros Pre'!$J$2:J5049,MATCH(ROW()-ROW($B$1),'Pasajeros Pre'!$O$2:$O$4995,0)),"") -> Mérida | L56: =IFERROR(INDEX('Pasajeros Pre'!$K$2:K5049,MATCH(ROW()-ROW($B$1),'Pasajeros Pre'!$O$2:$O$4995,0)),"") -> 46163.256 | M56: =IFERROR(INDEX('Pasajeros Pre'!$L$2:L5049,MATCH(ROW()-ROW($B$1),'Pasajeros Pre'!$O$2:$O$4995,0)),"") -> J | N56: =ROUNDDOWN(HOUR(F56),1)+1 -> 17 | O56: =VLOOKUP(N56,'Time Chart'!$A$2:$D$25,4,0) -> 16:00 A 16:59 | P56: =ROUNDDOWN(HOUR(L56),1)+1 -> 7 | Q56: =VLOOKUP(P56,'Time Chart'!$A$2:$D$25,4,0) -> 06:00 A 06:59 | R56: =TEXT(F56,"dd/mm/aaaa") -> 20/05/2026 | S56: =COUNTIFS(Hoja1!$R$2,"="&R56) -> 1 | T56: =TEXT(L56,"dd/mm/aaaa") -> 21/05/2026 | U56: =COUNTIFS(Hoja1!$R$2,"="&T56) -> 0
A57: =ROW(A56) -> 56 | B57: =IFERROR(INDEX('Pasajeros Pre'!$A$2:A5050,MATCH(ROW()-ROW($B$1),'Pasajeros Pre'!$O$2:$O$4995,0)),"") -> Flight scheduled | C57: =IFERROR(INDEX('Pasajeros Pre'!$B$2:$B$195,MATCH(ROW()-ROW($A$1),'Pasajeros Pre'!$O$2:$O$195,0)),"") -> Viva | D57: =IFERROR(INDEX('Pasajeros Pre'!$C$2:C5050,MATCH(ROW()-ROW($B$1),'Pasajeros Pre'!$O$2:$O$4995,0)),"") -> 320 | E57: =IFERROR(INDEX('Pasajeros Pre'!$D$2:D5050,MATCH(ROW()-ROW($B$1),'Pasajeros Pre'!$O$2:$O$4995,0)),"") -> VB 7434 | F57: =IFERROR(INDEX('Pasajeros Pre'!$E$2:E5050,MATCH(ROW()-ROW($B$1),'Pasajeros Pre'!$O$2:$O$4995,0)),"") -> 46162.708 | G57: =IFERROR(INDEX('Pasajeros Pre'!$F$2:F5050,MATCH(ROW()-ROW($B$1),'Pasajeros Pre'!$O$2:$O$4995,0)),"") -> Ciudad Juárez | H57: =IFERROR(INDEX('Pasajeros Pre'!$G$2:G5050,MATCH(ROW()-ROW($B$1),'Pasajeros Pre'!$O$2:$O$4995,0)),"") -> 3 | I57: =IFERROR(INDEX('Pasajeros Pre'!$H$2:H5050,MATCH(ROW()-ROW($B$1),'Pasajeros Pre'!$O$2:$O$4995,0)),"") -> 504 | J57: =IFERROR(INDEX('Pasajeros Pre'!$I$2:I5050,MATCH(ROW()-ROW($B$1),'Pasajeros Pre'!$O$2:$O$4995,0)),"") -> VB 7434 | K57: =IFERROR(INDEX('Pasajeros Pre'!$J$2:J5050,MATCH(ROW()-ROW($B$1),'Pasajeros Pre'!$O$2:$O$4995,0)),"") -> Veracruz | L57: =IFERROR(INDEX('Pasajeros Pre'!$K$2:K5050,MATCH(ROW()-ROW($B$1),'Pasajeros Pre'!$O$2:$O$4995,0)),"") -> 46162.729 | M57: =IFERROR(INDEX('Pasajeros Pre'!$L$2:L5050,MATCH(ROW()-ROW($B$1),'Pasajeros Pre'!$O$2:$O$4995,0)),"") -> J | N57: =ROUNDDOWN(HOUR(F57),1)+1 -> 18 | O57: =VLOOKUP(N57,'Time Chart'!$A$2:$D$25,4,0) -> 17:00 A 17:59 | P57: =ROUNDDOWN(HOUR(L57),1)+1 -> 18 | Q57: =VLOOKUP(P57,'Time Chart'!$A$2:$D$25,4,0) -> 17:00 A 17:59 | R57: =TEXT(F57,"dd/mm/aaaa") -> 20/05/2026 | S57: =COUNTIFS(Hoja1!$R$2,"="&R57) -> 1 | T57: =TEXT(L57,"dd/mm/aaaa") -> 20/05/2026 | U57: =COUNTIFS(Hoja1!$R$2,"="&T57) -> 1
A58: =ROW(A57) -> 57 | B58: =IFERROR(INDEX('Pasajeros Pre'!$A$2:A5051,MATCH(ROW()-ROW($B$1),'Pasajeros Pre'!$O$2:$O$4995,0)),"") -> Flight scheduled | C58: =IFERROR(INDEX('Pasajeros Pre'!$B$2:$B$195,MATCH(ROW()-ROW($A$1),'Pasajeros Pre'!$O$2:$O$195,0)),"") -> Viva | D58: =IFERROR(INDEX('Pasajeros Pre'!$C$2:C5051,MATCH(ROW()-ROW($B$1),'Pasajeros Pre'!$O$2:$O$4995,0)),"") -> 321 | E58: =IFERROR(INDEX('Pasajeros Pre'!$D$2:D5051,MATCH(ROW()-ROW($B$1),'Pasajeros Pre'!$O$2:$O$4995,0)),"") -> VB 7417 | F58: =IFERROR(INDEX('Pasajeros Pre'!$E$2:E5051,MATCH(ROW()-ROW($B$1),'Pasajeros Pre'!$O$2:$O$4995,0)),"") -> 46162.708 | G58: =IFERROR(INDEX('Pasajeros Pre'!$F$2:F5051,MATCH(ROW()-ROW($B$1),'Pasajeros Pre'!$O$2:$O$4995,0)),"") -> Culiacán | H58: =IFERROR(INDEX('Pasajeros Pre'!$G$2:G5051,MATCH(ROW()-ROW($B$1),'Pasajeros Pre'!$O$2:$O$4995,0)),"") -> 3 | I58: =IFERROR(INDEX('Pasajeros Pre'!$H$2:H5051,MATCH(ROW()-ROW($B$1),'Pasajeros Pre'!$O$2:$O$4995,0)),"") -> 115B | J58: =IFERROR(INDEX('Pasajeros Pre'!$I$2:I5051,MATCH(ROW()-ROW($B$1),'Pasajeros Pre'!$O$2:$O$4995,0)),"") -> VB 7417 | K58: =IFERROR(INDEX('Pasajeros Pre'!$J$2:J5051,MATCH(ROW()-ROW($B$1),'Pasajeros Pre'!$O$2:$O$4995,0)),"") -> Cancún | L58: =IFERROR(INDEX('Pasajeros Pre'!$K$2:K5051,MATCH(ROW()-ROW($B$1),'Pasajeros Pre'!$O$2:$O$4995,0)),"") -> 46162.74 | M58: =IFERROR(INDEX('Pasajeros Pre'!$L$2:L5051,MATCH(ROW()-ROW($B$1),'Pasajeros Pre'!$O$2:$O$4995,0)),"") -> J | N58: =ROUNDDOWN(HOUR(F58),1)+1 -> 18 | O58: =VLOOKUP(N58,'Time Chart'!$A$2:$D$25,4,0) -> 17:00 A 17:59 | P58: =ROUNDDOWN(HOUR(L58),1)+1 -> 18 | Q58: =VLOOKUP(P58,'Time Chart'!$A$2:$D$25,4,0) -> 17:00 A 17:59 | R58: =TEXT(F58,"dd/mm/aaaa") -> 20/05/2026 | S58: =COUNTIFS(Hoja1!$R$2,"="&R58) -> 1 | T58: =TEXT(L58,"dd/mm/aaaa") -> 20/05/2026 | U58: =COUNTIFS(Hoja1!$R$2,"="&T58) -> 1
A59: =ROW(A58) -> 58 | B59: =IFERROR(INDEX('Pasajeros Pre'!$A$2:A5052,MATCH(ROW()-ROW($B$1),'Pasajeros Pre'!$O$2:$O$4995,0)),"") -> Flight scheduled | C59: =IFERROR(INDEX('Pasajeros Pre'!$B$2:$B$195,MATCH(ROW()-ROW($A$1),'Pasajeros Pre'!$O$2:$O$195,0)),"") -> Viva | D59: =IFERROR(INDEX('Pasajeros Pre'!$C$2:C5052,MATCH(ROW()-ROW($B$1),'Pasajeros Pre'!$O$2:$O$4995,0)),"") -> 32A | E59: =IFERROR(INDEX('Pasajeros Pre'!$D$2:D5052,MATCH(ROW()-ROW($B$1),'Pasajeros Pre'!$O$2:$O$4995,0)),"") -> VB 7304 | F59: =IFERROR(INDEX('Pasajeros Pre'!$E$2:E5052,MATCH(ROW()-ROW($B$1),'Pasajeros Pre'!$O$2:$O$4995,0)),"") -> 46162.712 | G59: =IFERROR(INDEX('Pasajeros Pre'!$F$2:F5052,MATCH(ROW()-ROW($B$1),'Pasajeros Pre'!$O$2:$O$4995,0)),"") -> Guadalajara | H59: =IFERROR(INDEX('Pasajeros Pre'!$G$2:G5052,MATCH(ROW()-ROW($B$1),'Pasajeros Pre'!$O$2:$O$4995,0)),"") -> 1 | I59: =IFERROR(INDEX('Pasajeros Pre'!$H$2:H5052,MATCH(ROW()-ROW($B$1),'Pasajeros Pre'!$O$2:$O$4995,0)),"") -> 107B | J59: =IFERROR(INDEX('Pasajeros Pre'!$I$2:I5052,MATCH(ROW()-ROW($B$1),'Pasajeros Pre'!$O$2:$O$4995,0)),"") -> VB 7304 | K59: =IFERROR(INDEX('Pasajeros Pre'!$J$2:J5052,MATCH(ROW()-ROW($B$1),'Pasajeros Pre'!$O$2:$O$4995,0)),"") -> Tampico | L59: =IFERROR(INDEX('Pasajeros Pre'!$K$2:K5052,MATCH(ROW()-ROW($B$1),'Pasajeros Pre'!$O$2:$O$4995,0)),"") -> 46162.736 | M59: =IFERROR(INDEX('Pasajeros Pre'!$L$2:L5052,MATCH(ROW()-ROW($B$1),'Pasajeros Pre'!$O$2:$O$4995,0)),"") -> J | N59: =ROUNDDOWN(HOUR(F59),1)+1 -> 18 | O59: =VLOOKUP(N59,'Time Chart'!$A$2:$D$25,4,0) -> 17:00 A 17:59 | P59: =ROUNDDOWN(HOUR(L59),1)+1 -> 18 | Q59: =VLOOKUP(P59,'Time Chart'!$A$2:$D$25,4,0) -> 17:00 A 17:59 | R59: =TEXT(F59,"dd/mm/aaaa") -> 20/05/2026 | S59: =COUNTIFS(Hoja1!$R$2,"="&R59) -> 1 | T59: =TEXT(L59,"dd/mm/aaaa") -> 20/05/2026 | U59: =COUNTIFS(Hoja1!$R$2,"="&T59) -> 1
A60: =ROW(A59) -> 59 | B60: =IFERROR(INDEX('Pasajeros Pre'!$A$2:A5053,MATCH(ROW()-ROW($B$1),'Pasajeros Pre'!$O$2:$O$4995,0)),"") -> Flight scheduled | C60: =IFERROR(INDEX('Pasajeros Pre'!$B$2:$B$195,MATCH(ROW()-ROW($A$1),'Pasajeros Pre'!$O$2:$O$195,0)),"") -> Aerus | D60: =IFERROR(INDEX('Pasajeros Pre'!$C$2:C5053,MATCH(ROW()-ROW($B$1),'Pasajeros Pre'!$O$2:$O$4995,0)),"") -> CNF | E60: =IFERROR(INDEX('Pasajeros Pre'!$D$2:D5053,MATCH(ROW()-ROW($B$1),'Pasajeros Pre'!$O$2:$O$4995,0)),"") -> ZV 361 | F60: =IFERROR(INDEX('Pasajeros Pre'!$E$2:E5053,MATCH(ROW()-ROW($B$1),'Pasajeros Pre'!$O$2:$O$4995,0)),"") -> 46162.712 | G60: =IFERROR(INDEX('Pasajeros Pre'!$F$2:F5053,MATCH(ROW()-ROW($B$1),'Pasajeros Pre'!$O$2:$O$4995,0)),"") -> Ciudad Victoria | H60: =IFERROR(INDEX('Pasajeros Pre'!$G$2:G5053,MATCH(ROW()-ROW($B$1),'Pasajeros Pre'!$O$2:$O$4995,0)),"") -> 2 | I60: =IFERROR(INDEX('Pasajeros Pre'!$H$2:H5053,MATCH(ROW()-ROW($B$1),'Pasajeros Pre'!$O$2:$O$4995,0)),"") -> 501 | J60: =IFERROR(INDEX('Pasajeros Pre'!$I$2:I5053,MATCH(ROW()-ROW($B$1),'Pasajeros Pre'!$O$2:$O$4995,0)),"") -> ZV 303 | K60: =IFERROR(INDEX('Pasajeros Pre'!$J$2:J5053,MATCH(ROW()-ROW($B$1),'Pasajeros Pre'!$O$2:$O$4995,0)),"") -> Ixtepec | L60: =IFERROR(INDEX('Pasajeros Pre'!$K$2:K5053,MATCH(ROW()-ROW($B$1),'Pasajeros Pre'!$O$2:$O$4995,0)),"") -> 46163.51 | M60: =IFERROR(INDEX('Pasajeros Pre'!$L$2:L5053,MATCH(ROW()-ROW($B$1),'Pasajeros Pre'!$O$2:$O$4995,0)),"") -> J | N60: =ROUNDDOWN(HOUR(F60),1)+1 -> 18 | O60: =VLOOKUP(N60,'Time Chart'!$A$2:$D$25,4,0) -> 17:00 A 17:59 | P60: =ROUNDDOWN(HOUR(L60),1)+1 -> 13 | Q60: =VLOOKUP(P60,'Time Chart'!$A$2:$D$25,4,0) -> 12:00 A 12:59 | R60: =TEXT(F60,"dd/mm/aaaa") -> 20/05/2026 | S60: =COUNTIFS(Hoja1!$R$2,"="&R60) -> 1 | T60: =TEXT(L60,"dd/mm/aaaa") -> 21/05/2026 | U60: =COUNTIFS(Hoja1!$R$2,"="&T60) -> 0
A61: =ROW(A60) -> 60 | B61: =IFERROR(INDEX('Pasajeros Pre'!$A$2:A5054,MATCH(ROW()-ROW($B$1),'Pasajeros Pre'!$O$2:$O$4995,0)),"") -> Flight scheduled | C61: =IFERROR(INDEX('Pasajeros Pre'!$B$2:$B$195,MATCH(ROW()-ROW($A$1),'Pasajeros Pre'!$O$2:$O$195,0)),"") -> Aeromexico | D61: =IFERROR(INDEX('Pasajeros Pre'!$C$2:C5054,MATCH(ROW()-ROW($B$1),'Pasajeros Pre'!$O$2:$O$4995,0)),"") -> E90 | E61: =IFERROR(INDEX('Pasajeros Pre'!$D$2:D5054,MATCH(ROW()-ROW($B$1),'Pasajeros Pre'!$O$2:$O$4995,0)),"") -> AM 875 | F61: =IFERROR(INDEX('Pasajeros Pre'!$E$2:E5054,MATCH(ROW()-ROW($B$1),'Pasajeros Pre'!$O$2:$O$4995,0)),"") -> 46162.72 | G61: =IFERROR(INDEX('Pasajeros Pre'!$F$2:F5054,MATCH(ROW()-ROW($B$1),'Pasajeros Pre'!$O$2:$O$4995,0)),"") -> Mérida | H61: =IFERROR(INDEX('Pasajeros Pre'!$G$2:G5054,MATCH(ROW()-ROW($B$1),'Pasajeros Pre'!$O$2:$O$4995,0)),"") -> 3 | I61: =IFERROR(INDEX('Pasajeros Pre'!$H$2:H5054,MATCH(ROW()-ROW($B$1),'Pasajeros Pre'!$O$2:$O$4995,0)),"") -> 110A | J61: =IFERROR(INDEX('Pasajeros Pre'!$I$2:I5054,MATCH(ROW()-ROW($B$1),'Pasajeros Pre'!$O$2:$O$4995,0)),"") -> AM 872 | K61: =IFERROR(INDEX('Pasajeros Pre'!$J$2:J5054,MATCH(ROW()-ROW($B$1),'Pasajeros Pre'!$O$2:$O$4995,0)),"") -> Veracruz | L61: =IFERROR(INDEX('Pasajeros Pre'!$K$2:K5054,MATCH(ROW()-ROW($B$1),'Pasajeros Pre'!$O$2:$O$4995,0)),"") -> 46162.748 | M61: =IFERROR(INDEX('Pasajeros Pre'!$L$2:L5054,MATCH(ROW()-ROW($B$1),'Pasajeros Pre'!$O$2:$O$4995,0)),"") -> J | N61: =ROUNDDOWN(HOUR(F61),1)+1 -> 18 | O61: =VLOOKUP(N61,'Time Chart'!$A$2:$D$25,4,0) -> 17:00 A 17:59 | P61: =ROUNDDOWN(HOUR(L61),1)+1 -> 18 | Q61: =VLOOKUP(P61,'Time Chart'!$A$2:$D$25,4,0) -> 17:00 A 17:59 | R61: =TEXT(F61,"dd/mm/aaaa") -> 20/05/2026 | S61: =COUNTIFS(Hoja1!$R$2,"="&R61) -> 1 | T61: =TEXT(L61,"dd/mm/aaaa") -> 20/05/2026 | U61: =COUNTIFS(Hoja1!$R$2,"="&T61) -> 1
A62: =ROW(A61) -> 61 | B62: =IFERROR(INDEX('Pasajeros Pre'!$A$2:A5055,MATCH(ROW()-ROW($B$1),'Pasajeros Pre'!$O$2:$O$4995,0)),"") -> Flight scheduled | C62: =IFERROR(INDEX('Pasajeros Pre'!$B$2:$B$195,MATCH(ROW()-ROW($A$1),'Pasajeros Pre'!$O$2:$O$195,0)),"") -> Viva | D62: =IFERROR(INDEX('Pasajeros Pre'!$C$2:C5055,MATCH(ROW()-ROW($B$1),'Pasajeros Pre'!$O$2:$O$4995,0)),"") -> 321 | E62: =IFERROR(INDEX('Pasajeros Pre'!$D$2:D5055,MATCH(ROW()-ROW($B$1),'Pasajeros Pre'!$O$2:$O$4995,0)),"") -> VB 7443 | F62: =IFERROR(INDEX('Pasajeros Pre'!$E$2:E5055,MATCH(ROW()-ROW($B$1),'Pasajeros Pre'!$O$2:$O$4995,0)),"") -> 46162.722 | G62: =IFERROR(INDEX('Pasajeros Pre'!$F$2:F5055,MATCH(ROW()-ROW($B$1),'Pasajeros Pre'!$O$2:$O$4995,0)),"") -> Cancún | H62: =IFERROR(INDEX('Pasajeros Pre'!$G$2:G5055,MATCH(ROW()-ROW($B$1),'Pasajeros Pre'!$O$2:$O$4995,0)),"") -> 1 | I62: =IFERROR(INDEX('Pasajeros Pre'!$H$2:H5055,MATCH(ROW()-ROW($B$1),'Pasajeros Pre'!$O$2:$O$4995,0)),"") -> 107A | J62: =IFERROR(INDEX('Pasajeros Pre'!$I$2:I5055,MATCH(ROW()-ROW($B$1),'Pasajeros Pre'!$O$2:$O$4995,0)),"") -> VB 7443 | K62: =IFERROR(INDEX('Pasajeros Pre'!$J$2:J5055,MATCH(ROW()-ROW($B$1),'Pasajeros Pre'!$O$2:$O$4995,0)),"") -> Los Cabos | L62: =IFERROR(INDEX('Pasajeros Pre'!$K$2:K5055,MATCH(ROW()-ROW($B$1),'Pasajeros Pre'!$O$2:$O$4995,0)),"") -> 46162.75 | M62: =IFERROR(INDEX('Pasajeros Pre'!$L$2:L5055,MATCH(ROW()-ROW($B$1),'Pasajeros Pre'!$O$2:$O$4995,0)),"") -> J | N62: =ROUNDDOWN(HOUR(F62),1)+1 -> 18 | O62: =VLOOKUP(N62,'Time Chart'!$A$2:$D$25,4,0) -> 17:00 A 17:59 | P62: =ROUNDDOWN(HOUR(L62),1)+1 -> 19 | Q62: =VLOOKUP(P62,'Time Chart'!$A$2:$D$25,4,0) -> 18:00 A 18:59 | R62: =TEXT(F62,"dd/mm/aaaa") -> 20/05/2026 | S62: =COUNTIFS(Hoja1!$R$2,"="&R62) -> 1 | T62: =TEXT(L62,"dd/mm/aaaa") -> 20/05/2026 | U62: =COUNTIFS(Hoja1!$R$2,"="&T62) -> 1
A63: =ROW(A62) -> 62 | B63: =IFERROR(INDEX('Pasajeros Pre'!$A$2:A5056,MATCH(ROW()-ROW($B$1),'Pasajeros Pre'!$O$2:$O$4995,0)),"") -> Flight scheduled | C63: =IFERROR(INDEX('Pasajeros Pre'!$B$2:$B$195,MATCH(ROW()-ROW($A$1),'Pasajeros Pre'!$O$2:$O$195,0)),"") -> Viva | D63: =IFERROR(INDEX('Pasajeros Pre'!$C$2:C5056,MATCH(ROW()-ROW($B$1),'Pasajeros Pre'!$O$2:$O$4995,0)),"") -> 32A | E63: =IFERROR(INDEX('Pasajeros Pre'!$D$2:D5056,MATCH(ROW()-ROW($B$1),'Pasajeros Pre'!$O$2:$O$4995,0)),"") -> VB 7016 | F63: =IFERROR(INDEX('Pasajeros Pre'!$E$2:E5056,MATCH(ROW()-ROW($B$1),'Pasajeros Pre'!$O$2:$O$4995,0)),"") -> 46162.729 | G63: =IFERROR(INDEX('Pasajeros Pre'!$F$2:F5056,MATCH(ROW()-ROW($B$1),'Pasajeros Pre'!$O$2:$O$4995,0)),"") -> Monterrey | H63: =IFERROR(INDEX('Pasajeros Pre'!$G$2:G5056,MATCH(ROW()-ROW($B$1),'Pasajeros Pre'!$O$2:$O$4995,0)),"") -> 2 | I63: =IFERROR(INDEX('Pasajeros Pre'!$H$2:H5056,MATCH(ROW()-ROW($B$1),'Pasajeros Pre'!$O$2:$O$4995,0)),"") -> 503 | J63: =IFERROR(INDEX('Pasajeros Pre'!$I$2:I5056,MATCH(ROW()-ROW($B$1),'Pasajeros Pre'!$O$2:$O$4995,0)),"") -> VB 7016 | K63: =IFERROR(INDEX('Pasajeros Pre'!$J$2:J5056,MATCH(ROW()-ROW($B$1),'Pasajeros Pre'!$O$2:$O$4995,0)),"") -> Acapulco | L63: =IFERROR(INDEX('Pasajeros Pre'!$K$2:K5056,MATCH(ROW()-ROW($B$1),'Pasajeros Pre'!$O$2:$O$4995,0)),"") -> 46162.753 | M63: =IFERROR(INDEX('Pasajeros Pre'!$L$2:L5056,MATCH(ROW()-ROW($B$1),'Pasajeros Pre'!$O$2:$O$4995,0)),"") -> J | N63: =ROUNDDOWN(HOUR(F63),1)+1 -> 18 | O63: =VLOOKUP(N63,'Time Chart'!$A$2:$D$25,4,0) -> 17:00 A 17:59 | P63: =ROUNDDOWN(HOUR(L63),1)+1 -> 19 | Q63: =VLOOKUP(P63,'Time Chart'!$A$2:$D$25,4,0) -> 18:00 A 18:59 | R63: =TEXT(F63,"dd/mm/aaaa") -> 20/05/2026 | S63: =COUNTIFS(Hoja1!$R$2,"="&R63) -> 1 | T63: =TEXT(L63,"dd/mm/aaaa") -> 20/05/2026 | U63: =COUNTIFS(Hoja1!$R$2,"="&T63) -> 1
